Workbook

Sheet 目录及说明
A1: 羊喜市中期预算模型 V60 目录及说明
A3: 版本 | B3: V60 渠道二维汇总、汇总损益费用链路与目录重建
A4: 表格逻辑 | B4: https://jv8fym591u8.feishu.cn/docx/YzETdWRa3oLB9rxM8i7ccsNAnfg?from=from_copylink
A5: 输出规则 | B5: 目录、总表、说明、假设、测算、辅助、参考；各工作表均可通过目录跳转。
A6: 本版重点 | B6: 统一全表字体为等线；渠道费用明细按科目名称映射，渠道总贡献与汇总损益表口径一致。
A7: 校验单位 | B7: 金额单位均为万元；测算与总表的1-6月列保留分组隐藏规则。
A8: 序号 | B8: 工作表 | C8: 类型 | D8: 计算角色 | E8: 定义/用途 | F8: 跳转 | G8: 显示状态 | H8: 备注
A9: 1 | B9: 目录及说明 | C9: 目录 | D9: 导航 | E9: 模型导航、版本与维护规则 | F9: =HYPERLINK("#'目录及说明'!A1","当前") -> 当前 | G9: 显示 | H9: 当前工作表
A10: 2 | B10: 总表-汇总损益表 | C10: 总表 | D10: 汇总 | E10: 公司合并损益、其他业务收入与净利润 | F10: =HYPERLINK("#'总表-汇总损益表'!A1","打开") -> 打开 | G10: 显示 | H10: 集团口径总览
A11: 3 | B11: 总表-渠道二维汇总 | C11: 总表 | D11: 汇总 | E11: 渠道收入、成本、费用及贡献横向对比 | F11: =HYPERLINK("#'总表-渠道二维汇总'!A1","打开") -> 打开 | G11: 显示 | H11: 仅展示渠道及渠道总贡献
A12: 4 | B12: 费用科目说明 | C12: 说明 | D12: 说明 | E12: 预算费用科目与财报科目映射说明 | F12: =HYPERLINK("#'费用科目说明'!A1","打开") -> 打开 | G12: 显示 | H12: 不参与计算，建议保留审计说明
A13: 5 | B13: 假设-财务口径 | C13: 假设/输入 | D13: 驱动 | E13: 税率、返利及整体经营财务假设 | F13: =HYPERLINK("#'假设-财务口径'!A1","打开") -> 打开 | G13: 显示 | H13: 直接参与整体经营及所得税计算
A14: 6 | B14: 假设-人工成本固定额 | C14: 假设/输入 | D14: 驱动 | E14: 各渠道固定薪资及奖金规则 | F14: =HYPERLINK("#'假设-人工成本固定额'!A1","打开") -> 打开 | G14: 隐藏 | H14: 驱动渠道人工成本
A15: 7 | B15: 假设-产品价值链定价 | C15: 假设/输入 | D15: 驱动 | E15: 集团采购、内部拿货及产品定价假设 | F15: =HYPERLINK("#'假设-产品价值链定价'!A1","打开") -> 打开 | G15: 隐藏 | H15: 驱动整体经营剪刀差测算
A16: 8 | B16: 假设-成本与任务量 | C16: 假设/输入 | D16: 驱动 | E16: 产品采购成本与SALEIN任务分解 | F16: =HYPERLINK("#'假设-成本与任务量'!A1","打开") -> 打开 | G16: 显示 | H16: 驱动产品成本与任务目标
A17: 9 | B17: 参考值-平台主推SKU占比 | C17: 参考 | D17: 引用源 | E17: 平台主推SKU结构及成交占比 | F17: =HYPERLINK("#'参考值-平台主推SKU占比'!A1","打开") -> 打开 | G17: 隐藏 | H17: 驱动平台主推机制
A18: 10 | B18: 假设-平台主推机制 | C18: 假设/输入 | D18: 驱动 | E18: 渠道机制、到手价及主品成本结构 | F18: =HYPERLINK("#'假设-平台主推机制'!A1","打开") -> 打开 | G18: 隐藏 | H18: 驱动渠道收入与产品成本
A19: 11 | B19: 假设-目标渠道分解 | C19: 假设/输入 | D19: 驱动 | E19: 渠道SALEIN任务与月度目标 | F19: =HYPERLINK("#'假设-目标渠道分解'!A1","打开") -> 打开 | G19: 显示 | H19: 驱动渠道滚动目标
A20: 12 | B20: 参考值-平台费用率分析 | C20: 参考 | D20: 引用源 | E20: 财务口径平台1-12月实际费用与收入数据 | F20: =HYPERLINK("#'参考值-平台费用率分析'!A1","打开") -> 打开 | G20: 隐藏 | H20: 销售费用率与实际达成取数源
A21: 13 | B21: 假设-销售费用率 | C21: 假设/输入 | D21: 驱动 | E21: 渠道月度费用率、历史参考及运营调整 | F21: =HYPERLINK("#'假设-销售费用率'!A1","打开") -> 打开 | G21: 显示 | H21: 驱动渠道销售费用
A22: 14 | B22: 假设-ROI月度滚动 | C22: 假设/输入 | D22: 驱动 | E22: 广告投流ROI月度假设 | F22: =HYPERLINK("#'假设-ROI月度滚动'!A1","打开") -> 打开 | G22: 显示 | H22: 驱动ROI相关费用
A23: 15 | B23: 测算-高个子抖音 | C23: 测算 | D23: 计算 | E23: 抖音渠道收入、成本、费用与贡献利润 | F23: =HYPERLINK("#'测算-高个子抖音'!A1","打开") -> 打开 | G23: 显示 | H23: 渠道测算
A24: 16 | B24: 测算-高个子视频号 | C24: 测算 | D24: 计算 | E24: 视频号渠道收入、成本、费用与贡献利润 | F24: =HYPERLINK("#'测算-高个子视频号'!A1","打开") -> 打开 | G24: 显示 | H24: 渠道测算
A25: 17 | B25: 测算-天猫淘宝 | C25: 测算 | D25: 计算 | E25: 天猫淘宝渠道收入、成本、费用与贡献利润 | F25: =HYPERLINK("#'测算-天猫淘宝'!A1","打开") -> 打开 | G25: 显示 | H25: 渠道测算
A26: 18 | B26: 测算-拼多多 | C26: 测算 | D26: 计算 | E26: 拼多多渠道收入、成本、费用与贡献利润 | F26: =HYPERLINK("#'测算-拼多多'!A1","打开") -> 打开 | G26: 显示 | H26: 渠道测算
A27: 19 | B27: 测算-京东POP | C27: 测算 | D27: 计算 | E27: 京东POP渠道收入、成本、费用与贡献利润 | F27: =HYPERLINK("#'测算-京东POP'!A1","打开") -> 打开 | G27: 显示 | H27: 渠道测算
A28: 20 | B28: 测算-京东自营 | C28: 测算 | D28: 计算 | E28: 京东自营B2B供货、费用与贡献利润 | F28: =HYPERLINK("#'测算-京东自营'!A1","打开") -> 打开 | G28: 显示 | H28: 渠道测算
A29: 21 | B29: 测算-达播 | C29: 测算 | D29: 计算 | E29: 达播渠道收入、成本、费用与贡献利润 | F29: =HYPERLINK("#'测算-达播'!A1","打开") -> 打开 | G29: 显示 | H29: 渠道测算
A30: 22 | B30: 测算-私域 | C30: 测算 | D30: 计算 | E30: 私域渠道独立业务测算 | F30: =HYPERLINK("#'测算-私域'!A1","打开") -> 打开 | G30: 显示 | H30: 业务部门薪资奖金按其测算口径
A31: 23 | B31: 测算-外部分销 | C31: 测算 | D31: 计算 | E31: 外部分销收入、成本、返佣与物流费用 | F31: =HYPERLINK("#'测算-外部分销'!A1","打开") -> 打开 | G31: 显示 | H31: 渠道测算
A32: 24 | B32: 测算-整体经营 | C32: 测算 | D32: 计算 | E32: 集团内部供货价差、返利及公司公共费用 | F32: =HYPERLINK("#'测算-整体经营'!A1","打开") -> 打开 | G32: 显示 | H32: 整体经营损益
A33: 25 | B33: 辅助-汇总损益长表 | C33: 辅助 | D33: 汇总辅助 | E33: 各渠道与整体经营的纵向汇总底表 | F33: =HYPERLINK("#'辅助-汇总损益长表'!A1","打开") -> 打开 | G33: 隐藏 | H33: 直接参与总表计算，不可删除
A34: 26 | B34: 辅助-机制测算 | C34: 辅助 | D34: 计算辅助 | E34: 平台机制的收入、主品成本及SKU拆分 | F34: =HYPERLINK("#'辅助-机制测算'!A1","打开") -> 打开 | G34: 隐藏 | H34: 直接参与渠道测算，不可删除

Sheet 总表-汇总损益表
A1: 返回目录
B2: 公司层面汇总损益（万元）
D6: 科目明细 | E6: 说明 | F6: 驱动 | H6: 2026-01 | I6: 2026-02 | J6: 2026-03 | K6: 2026-04 | L6: 2026-05 | M6: 2026-06 | N6: 2026-07 | O6: 2026-08 | P6: 2026-09 | Q6: 2026-10 | R6: 2026-11 | S6: 2026-12 | U6: 全年合计 | V6: 中期合计
B7: 主营业务收入 | F7: 来自各渠道测算表 | H7: =SUMIFS('辅助-汇总损益长表'!$C$2:$C$242,'辅助-汇总损益长表'!$A$2:$A$242,"主营业务收入",'辅助-汇总损益长表'!$B$2:$B$242,H$6)-SUMIFS('辅助-汇总损益长表'!$M$2:$M$242,'辅助-汇总损益长表'!$A$2:$A$242,"主营业务收入",'辅助-汇总损益长表'!$B$2:$B$242,H$6) -> 1096.5403 | I7: =SUMIFS('辅助-汇总损益长表'!$C$2:$C$242,'辅助-汇总损益长表'!$A$2:$A$242,"主营业务收入",'辅助-汇总损益长表'!$B$2:$B$242,I$6)-SUMIFS('辅助-汇总损益长表'!$M$2:$M$242,'辅助-汇总损益长表'!$A$2:$A$242,"主营业务收入",'辅助-汇总损益长表'!$B$2:$B$242,I$6) -> 664.95961 | J7: =SUMIFS('辅助-汇总损益长表'!$C$2:$C$242,'辅助-汇总损益长表'!$A$2:$A$242,"主营业务收入",'辅助-汇总损益长表'!$B$2:$B$242,J$6)-SUMIFS('辅助-汇总损益长表'!$M$2:$M$242,'辅助-汇总损益长表'!$A$2:$A$242,"主营业务收入",'辅助-汇总损益长表'!$B$2:$B$242,J$6) -> 1012.2948 | K7: =SUMIFS('辅助-汇总损益长表'!$C$2:$C$242,'辅助-汇总损益长表'!$A$2:$A$242,"主营业务收入",'辅助-汇总损益长表'!$B$2:$B$242,K$6)-SUMIFS('辅助-汇总损益长表'!$M$2:$M$242,'辅助-汇总损益长表'!$A$2:$A$242,"主营业务收入",'辅助-汇总损益长表'!$B$2:$B$242,K$6) -> 977.84975 | L7: =SUMIFS('辅助-汇总损益长表'!$C$2:$C$242,'辅助-汇总损益长表'!$A$2:$A$242,"主营业务收入",'辅助-汇总损益长表'!$B$2:$B$242,L$6)-SUMIFS('辅助-汇总损益长表'!$M$2:$M$242,'辅助-汇总损益长表'!$A$2:$A$242,"主营业务收入",'辅助-汇总损益长表'!$B$2:$B$242,L$6) -> 1218.1032 | M7: =SUMIFS('辅助-汇总损益长表'!$C$2:$C$242,'辅助-汇总损益长表'!$A$2:$A$242,"主营业务收入",'辅助-汇总损益长表'!$B$2:$B$242,M$6)-SUMIFS('辅助-汇总损益长表'!$M$2:$M$242,'辅助-汇总损益长表'!$A$2:$A$242,"主营业务收入",'辅助-汇总损益长表'!$B$2:$B$242,M$6) -> 1240.5906 | N7: =SUMIFS('辅助-汇总损益长表'!$C$2:$C$242,'辅助-汇总损益长表'!$A$2:$A$242,"主营业务收入",'辅助-汇总损益长表'!$B$2:$B$242,N$6)-SUMIFS('辅助-汇总损益长表'!$M$2:$M$242,'辅助-汇总损益长表'!$A$2:$A$242,"主营业务收入",'辅助-汇总损益长表'!$B$2:$B$242,N$6) -> 791.84389 | O7: =SUMIFS('辅助-汇总损益长表'!$C$2:$C$242,'辅助-汇总损益长表'!$A$2:$A$242,"主营业务收入",'辅助-汇总损益长表'!$B$2:$B$242,O$6)-SUMIFS('辅助-汇总损益长表'!$M$2:$M$242,'辅助-汇总损益长表'!$A$2:$A$242,"主营业务收入",'辅助-汇总损益长表'!$B$2:$B$242,O$6) -> 1045.5994 | ... S7: =SUMIFS('辅助-汇总损益长表'!$C$2:$C$242,'辅助-汇总损益长表'!$A$2:$A$242,"主营业务收入",'辅助-汇总损益长表'!$B$2:$B$242,S$6)-SUMIFS('辅助-汇总损益长表'!$M$2:$M$242,'辅助-汇总损益长表'!$A$2:$A$242,"主营业务收入",'辅助-汇总损益长表'!$B$2:$B$242,S$6) -> 1463.1062 | U7: =SUM(H7:S7) -> 13949.584 | V7: =SUM(N7:S7) -> 7739.2455
B8: 主营业务成本 | F8: 来自各渠道测算表 | H8: =SUMIFS('辅助-汇总损益长表'!$C$2:$C$242,'辅助-汇总损益长表'!$A$2:$A$242,"主营业务成本",'辅助-汇总损益长表'!$B$2:$B$242,H$6) -> 413.97462 | I8: =SUMIFS('辅助-汇总损益长表'!$C$2:$C$242,'辅助-汇总损益长表'!$A$2:$A$242,"主营业务成本",'辅助-汇总损益长表'!$B$2:$B$242,I$6) -> 245.01229 | J8: =SUMIFS('辅助-汇总损益长表'!$C$2:$C$242,'辅助-汇总损益长表'!$A$2:$A$242,"主营业务成本",'辅助-汇总损益长表'!$B$2:$B$242,J$6) -> 437.01891 | K8: =SUMIFS('辅助-汇总损益长表'!$C$2:$C$242,'辅助-汇总损益长表'!$A$2:$A$242,"主营业务成本",'辅助-汇总损益长表'!$B$2:$B$242,K$6) -> 367.20972 | L8: =SUMIFS('辅助-汇总损益长表'!$C$2:$C$242,'辅助-汇总损益长表'!$A$2:$A$242,"主营业务成本",'辅助-汇总损益长表'!$B$2:$B$242,L$6) -> 463.40024 | M8: =SUMIFS('辅助-汇总损益长表'!$C$2:$C$242,'辅助-汇总损益长表'!$A$2:$A$242,"主营业务成本",'辅助-汇总损益长表'!$B$2:$B$242,M$6) -> 451.4047 | N8: =SUMIFS('辅助-汇总损益长表'!$C$2:$C$242,'辅助-汇总损益长表'!$A$2:$A$242,"主营业务成本",'辅助-汇总损益长表'!$B$2:$B$242,N$6) -> 284.77935 | O8: =SUMIFS('辅助-汇总损益长表'!$C$2:$C$242,'辅助-汇总损益长表'!$A$2:$A$242,"主营业务成本",'辅助-汇总损益长表'!$B$2:$B$242,O$6) -> 375.49932 | ... S8: =SUMIFS('辅助-汇总损益长表'!$C$2:$C$242,'辅助-汇总损益长表'!$A$2:$A$242,"主营业务成本",'辅助-汇总损益长表'!$B$2:$B$242,S$6) -> 524.78257 | U8: =SUM(H8:S8) -> 5155.1438 | V8: =SUM(N8:S8) -> 2777.1234
B9: 毛利 | F9: 公式计算 | H9: =H7-H8 -> 682.56571 | I9: =I7-I8 -> 419.94732 | J9: =J7-J8 -> 575.27586 | K9: =K7-K8 -> 610.64003 | L9: =L7-L8 -> 754.70294 | M9: =M7-M8 -> 789.18587 | N9: =N7-N8 -> 507.06454 | O9: =O7-O8 -> 670.10008 | ... S9: =S7-S8 -> 938.3236 | U9: =SUM(H9:S9) -> 8794.4399 | V9: =SUM(N9:S9) -> 4962.1222
B10: 毛利率 | F10: 公式计算 | H10: =IFERROR(H9/H7,0) -> 0.62247205 | I10: =IFERROR(I9/I7,0) -> 0.63153809 | J10: =IFERROR(J9/J7,0) -> 0.56828888 | K10: =IFERROR(K9/K7,0) -> 0.62447224 | L10: =IFERROR(L9/L7,0) -> 0.61957226 | M10: =IFERROR(M9/M7,0) -> 0.63613725 | N10: =IFERROR(N9/N7,0) -> 0.64035922 | O10: =IFERROR(O9/O7,0) -> 0.6408765 | ... S10: =IFERROR(S9/S7,0) -> 0.64132297 | U10: =IFERROR(U9/U7,0) -> 0.63044461 | V10: =IFERROR(V9/V7,0) -> 0.64116356
B11: 内部供货价差调整 | E11: 主体公司内部供货价差（管理口径） | F11: 测算-整体经营 | H11: ='测算-整体经营'!I$13 -> 43.350696 | I11: ='测算-整体经营'!J$13 -> 41.379724 | J11: ='测算-整体经营'!K$13 -> 58.838005 | K11: ='测算-整体经营'!L$13 -> 65.415322 | L11: ='测算-整体经营'!M$13 -> 76.059854 | M11: ='测算-整体经营'!N$13 -> 52.183939 | N11: ='测算-整体经营'!O$13 -> 25.488839 | O11: ='测算-整体经营'!P$13 -> 34.09001 | ... S11: ='测算-整体经营'!T$13 -> 48.250476 | U11: =SUM(H11:S11) -> 591.43413 | V11: =SUM(N11:S11) -> 254.20659
B12: 调整后毛利 | E12: 渠道毛利+内部供货价差 | F12: 公式计算 | H12: =H9+H11 -> 725.9164 | I12: =I9+I11 -> 461.32704 | J12: =J9+J11 -> 634.11387 | K12: =K9+K11 -> 676.05535 | L12: =L9+L11 -> 830.7628 | M12: =M9+M11 -> 841.36981 | N12: =N9+N11 -> 532.55338 | O12: =O9+O11 -> 704.19009 | ... S12: =S9+S11 -> 986.57408 | U12: =SUM(H12:S12) -> 9385.874 | V12: =SUM(N12:S12) -> 5216.3288
B13: 调整后毛利率 | E13: 调整后毛利/渠道主营业务收入 | F13: 公式计算 | H13: =IFERROR(H12/H7,0) -> 0.66200612 | I13: =IFERROR(I12/I7,0) -> 0.69376702 | J13: =IFERROR(J12/J7,0) -> 0.62641227 | K13: =IFERROR(K12/K7,0) -> 0.69136935 | L13: =IFERROR(L12/L7,0) -> 0.68201348 | M13: =IFERROR(M12/M7,0) -> 0.67820103 | N13: =IFERROR(N12/N7,0) -> 0.67254844 | O13: =IFERROR(O12/O7,0) -> 0.67347981 | ... S13: =IFERROR(S12/S7,0) -> 0.67430108 | U13: =IFERROR(U12/U7,0) -> 0.67284259 | V13: =IFERROR(V12/V7,0) -> 0.67400998
B14: 其他业务收入 | E14: 供应商达成返利及推广费支持 | F14: 测算-整体经营 | H14: =SUM(H15:H17) -> 0 | I14: =SUM(I15:I17) -> 38.32731 | J14: =SUM(J15:J17) -> 36.58473 | K14: =SUM(K15:K17) -> 57.214246 | L14: =SUM(L15:L17) -> 63.029398 | M14: =SUM(M15:M17) -> 72.440464 | N14: =SUM(N15:N17) -> 53.143506 | O14: =SUM(O15:O17) -> 29.541777 | ... S14: =SUM(S15:S17) -> 120.37413 | U14: =SUM(H14:S14) -> 587.13888 | V14: =SUM(N14:S14) -> 319.54273
C15: 达成返利 | D15: 季度达成返利（回款） | E15: 季度结算、下季度分月到账 | F15: 测算-整体经营 | H15: ='测算-整体经营'!I$17 -> 0 | I15: ='测算-整体经营'!J$17 -> 0 | J15: ='测算-整体经营'!K$17 -> 0 | K15: ='测算-整体经营'!L$17 -> 5.1942638 | L15: ='测算-整体经营'!M$17 -> 5.1942638 | M15: ='测算-整体经营'!N$17 -> 5.1942638 | N15: ='测算-整体经营'!O$17 -> 7.0065303 | O15: ='测算-整体经营'!P$17 -> 7.0065303 | ... S15: ='测算-整体经营'!T$17 -> 0 | U15: =SUM(H15:S15) -> 36.602382 | V15: =SUM(N15:S15) -> 21.019591
C16: 达成返利 | D16: 年度达成返利 | E16: 年度目标达成后确认 | F16: 测算-整体经营 | H16: ='测算-整体经营'!I$18 -> 0 | I16: ='测算-整体经营'!J$18 -> 0 | J16: ='测算-整体经营'!K$18 -> 0 | K16: ='测算-整体经营'!L$18 -> 0 | L16: ='测算-整体经营'!M$18 -> 0 | M16: ='测算-整体经营'!N$18 -> 0 | N16: ='测算-整体经营'!O$18 -> 0 | O16: ='测算-整体经营'!P$18 -> 0 | ... S16: ='测算-整体经营'!T$18 -> 70.29581 | U16: =SUM(H16:S16) -> 70.29581 | V16: =SUM(N16:S16) -> 70.29581
C17: 达成返利 | D17: 推广费支持（回款） | E17: 季度结算、下季度分月到账 | F17: 测算-整体经营 | H17: ='测算-整体经营'!I$19 -> 0 | I17: ='测算-整体经营'!J$19 -> 38.32731 | J17: ='测算-整体经营'!K$19 -> 36.58473 | K17: ='测算-整体经营'!L$19 -> 52.019982 | L17: ='测算-整体经营'!M$19 -> 57.835134 | M17: ='测算-整体经营'!N$19 -> 67.2462 | N17: ='测算-整体经营'!O$19 -> 46.136975 | O17: ='测算-整体经营'!P$19 -> 22.535246 | ... S17: ='测算-整体经营'!T$19 -> 50.078325 | U17: =SUM(H17:S17) -> 480.24069 | V17: =SUM(N17:S17) -> 228.22733
B18: 销售费用 | F18: 下列明细汇总 | H18: =SUM(H20,H29,H34,H38,H43) -> 490.21725 | I18: =SUM(I20,I29,I34,I38,I43) -> 308.16564 | J18: =SUM(J20,J29,J34,J38,J43) -> 661.62352 | K18: =SUM(K20,K29,K34,K38,K43) -> 432.60885 | L18: =SUM(L20,L29,L34,L38,L43) -> 566.72381 | M18: =SUM(M20,M29,M34,M38,M43) -> 657.77219 | N18: =SUM(N20,N29,N34,N38,N43) -> 460.36615 | O18: =SUM(O20,O29,O34,O38,O43) -> 598.93023 | ... S18: =SUM(S20,S29,S34,S38,S43) -> 822.274 | U18: =SUM(U20,U29,U34,U38,U43) -> 7519.8614 | V18: =SUM(V20,V29,V34,V38,V43) -> 4374.6607
B19: 销售费用率 | E19: 销售费用/收入 | F19: 公式计算 | H19: =IFERROR(H18/H7,0) -> 0.44705811 | I19: =IFERROR(I18/I7,0) -> 0.46343512 | J19: =IFERROR(J18/J7,0) -> 0.65358781 | K19: =IFERROR(K18/K7,0) -> 0.44240831 | L19: =IFERROR(L18/L7,0) -> 0.46525107 | M19: =IFERROR(M18/M7,0) -> 0.53020893 | N19: =IFERROR(N18/N7,0) -> 0.58138498 | O19: =IFERROR(O18/O7,0) -> 0.57281042 | ... S19: =IFERROR(S18/S7,0) -> 0.56200569 | U19: =IFERROR(U18/U7,0) -> 0.53907425 | V19: =IFERROR(V18/V7,0) -> 0.56525674
C20: 渠道投入 | H20: =SUM(H21:H28) -> 412.18124 | I20: =SUM(I21:I28) -> 249.59394 | J20: =SUM(J21:J28) -> 566.78644 | K20: =SUM(K21:K28) -> 353.13792 | L20: =SUM(L21:L28) -> 472.97887 | M20: =SUM(M21:M28) -> 545.4595 | N20: =SUM(N21:N28) -> 343.93451 | O20: =SUM(O21:O28) -> 460.4476 | ... S20: =SUM(S21:S28) -> 648.12293 | U20: =SUM(U21:U28) -> 6019.0674 | V20: =SUM(V21:V28) -> 3418.9295
D21: 广告投流费 | E21: 渠道测算费用明细 | F21: 各渠道测算表汇总 | H21: =SUM('测算-高个子抖音'!I$22)+SUM('测算-高个子视频号'!I$22)+SUM('测算-天猫淘宝'!I$21)+SUM('测算-拼多多'!I$22)+SUM('测算-京东POP'!I$22)+SUM('测算-达播'!I$23)+SUM('测算-私域'!I$22)+SUM('测算-外部分销'!I$22)++SUM('测算-京东自营'!I$21) -> 334.9911 | I21: =SUM('测算-高个子抖音'!J$22)+SUM('测算-高个子视频号'!J$22)+SUM('测算-天猫淘宝'!J$21)+SUM('测算-拼多多'!J$22)+SUM('测算-京东POP'!J$22)+SUM('测算-达播'!J$23)+SUM('测算-私域'!J$22)+SUM('测算-外部分销'!J$22)++SUM('测算-京东自营'!J$21) -> 214.39622 | J21: =SUM('测算-高个子抖音'!K$22)+SUM('测算-高个子视频号'!K$22)+SUM('测算-天猫淘宝'!K$21)+SUM('测算-拼多多'!K$22)+SUM('测算-京东POP'!K$22)+SUM('测算-达播'!K$23)+SUM('测算-私域'!K$22)+SUM('测算-外部分销'!K$22)++SUM('测算-京东自营'!K$21) -> 437.40128 | K21: =SUM('测算-高个子抖音'!L$22)+SUM('测算-高个子视频号'!L$22)+SUM('测算-天猫淘宝'!L$21)+SUM('测算-拼多多'!L$22)+SUM('测算-京东POP'!L$22)+SUM('测算-达播'!L$23)+SUM('测算-私域'!L$22)+SUM('测算-外部分销'!L$22)++SUM('测算-京东自营'!L$21) -> 301.87089 | L21: =SUM('测算-高个子抖音'!M$22)+SUM('测算-高个子视频号'!M$22)+SUM('测算-天猫淘宝'!M$21)+SUM('测算-拼多多'!M$22)+SUM('测算-京东POP'!M$22)+SUM('测算-达播'!M$23)+SUM('测算-私域'!M$22)+SUM('测算-外部分销'!M$22)++SUM('测算-京东自营'!M$21) -> 396.08316 | M21: =SUM('测算-高个子抖音'!N$22)+SUM('测算-高个子视频号'!N$22)+SUM('测算-天猫淘宝'!N$21)+SUM('测算-拼多多'!N$22)+SUM('测算-京东POP'!N$22)+SUM('测算-达播'!N$23)+SUM('测算-私域'!N$22)+SUM('测算-外部分销'!N$22)++SUM('测算-京东自营'!N$21) -> 440.42027 | N21: =SUM('测算-高个子抖音'!O$22)+SUM('测算-高个子视频号'!O$22)+SUM('测算-天猫淘宝'!O$21)+SUM('测算-拼多多'!O$22)+SUM('测算-京东POP'!O$22)+SUM('测算-达播'!O$23)+SUM('测算-私域'!O$22)+SUM('测算-外部分销'!O$22)++SUM('测算-京东自营'!O$21) -> 290.9505 | O21: =SUM('测算-高个子抖音'!P$22)+SUM('测算-高个子视频号'!P$22)+SUM('测算-天猫淘宝'!P$21)+SUM('测算-拼多多'!P$22)+SUM('测算-京东POP'!P$22)+SUM('测算-达播'!P$23)+SUM('测算-私域'!P$22)+SUM('测算-外部分销'!P$22)++SUM('测算-京东自营'!P$21) -> 389.58422 | ... S21: =SUM('测算-高个子抖音'!T$22)+SUM('测算-高个子视频号'!T$22)+SUM('测算-天猫淘宝'!T$21)+SUM('测算-拼多多'!T$22)+SUM('测算-京东POP'!T$22)+SUM('测算-达播'!T$23)+SUM('测算-私域'!T$22)+SUM('测算-外部分销'!T$22)++SUM('测算-京东自营'!T$21) -> 547.82399 | U21: =SUM('测算-高个子抖音'!V$22)+SUM('测算-高个子视频号'!V$22)+SUM('测算-天猫淘宝'!V$21)+SUM('测算-拼多多'!V$22)+SUM('测算-京东POP'!V$22)+SUM('测算-达播'!V$23)+SUM('测算-私域'!V$22)+SUM('测算-外部分销'!V$22)++SUM('测算-京东自营'!V$21) -> 5015.6696 | V21: =SUM('测算-高个子抖音'!W$22)+SUM('测算-高个子视频号'!W$22)+SUM('测算-天猫淘宝'!W$21)+SUM('测算-拼多多'!W$22)+SUM('测算-京东POP'!W$22)+SUM('测算-达播'!W$23)+SUM('测算-私域'!W$22)+SUM('测算-外部分销'!W$22)++SUM('测算-京东自营'!W$21) -> 2890.5067
D22: 媒介种草 | E22: 渠道测算费用明细 | F22: 各渠道测算表汇总 | H22: =SUM('测算-高个子抖音'!I$23)+SUM('测算-高个子视频号'!I$23)+SUM('测算-天猫淘宝'!I$22)+SUM('测算-拼多多'!I$23)+SUM('测算-京东POP'!I$23)+SUM('测算-达播'!I$24)+SUM('测算-私域'!I$23)+SUM('测算-外部分销'!I$23) -> 0 | I22: =SUM('测算-高个子抖音'!J$23)+SUM('测算-高个子视频号'!J$23)+SUM('测算-天猫淘宝'!J$22)+SUM('测算-拼多多'!J$23)+SUM('测算-京东POP'!J$23)+SUM('测算-达播'!J$24)+SUM('测算-私域'!J$23)+SUM('测算-外部分销'!J$23) -> 0 | J22: =SUM('测算-高个子抖音'!K$23)+SUM('测算-高个子视频号'!K$23)+SUM('测算-天猫淘宝'!K$22)+SUM('测算-拼多多'!K$23)+SUM('测算-京东POP'!K$23)+SUM('测算-达播'!K$24)+SUM('测算-私域'!K$23)+SUM('测算-外部分销'!K$23) -> 0 | K22: =SUM('测算-高个子抖音'!L$23)+SUM('测算-高个子视频号'!L$23)+SUM('测算-天猫淘宝'!L$22)+SUM('测算-拼多多'!L$23)+SUM('测算-京东POP'!L$23)+SUM('测算-达播'!L$24)+SUM('测算-私域'!L$23)+SUM('测算-外部分销'!L$23) -> 0 | L22: =SUM('测算-高个子抖音'!M$23)+SUM('测算-高个子视频号'!M$23)+SUM('测算-天猫淘宝'!M$22)+SUM('测算-拼多多'!M$23)+SUM('测算-京东POP'!M$23)+SUM('测算-达播'!M$24)+SUM('测算-私域'!M$23)+SUM('测算-外部分销'!M$23) -> 0 | M22: =SUM('测算-高个子抖音'!N$23)+SUM('测算-高个子视频号'!N$23)+SUM('测算-天猫淘宝'!N$22)+SUM('测算-拼多多'!N$23)+SUM('测算-京东POP'!N$23)+SUM('测算-达播'!N$24)+SUM('测算-私域'!N$23)+SUM('测算-外部分销'!N$23) -> 0 | N22: =SUM('测算-高个子抖音'!O$23)+SUM('测算-高个子视频号'!O$23)+SUM('测算-天猫淘宝'!O$22)+SUM('测算-拼多多'!O$23)+SUM('测算-京东POP'!O$23)+SUM('测算-达播'!O$24)+SUM('测算-私域'!O$23)+SUM('测算-外部分销'!O$23) -> 0 | O22: =SUM('测算-高个子抖音'!P$23)+SUM('测算-高个子视频号'!P$23)+SUM('测算-天猫淘宝'!P$22)+SUM('测算-拼多多'!P$23)+SUM('测算-京东POP'!P$23)+SUM('测算-达播'!P$24)+SUM('测算-私域'!P$23)+SUM('测算-外部分销'!P$23) -> 0 | ... S22: =SUM('测算-高个子抖音'!T$23)+SUM('测算-高个子视频号'!T$23)+SUM('测算-天猫淘宝'!T$22)+SUM('测算-拼多多'!T$23)+SUM('测算-京东POP'!T$23)+SUM('测算-达播'!T$24)+SUM('测算-私域'!T$23)+SUM('测算-外部分销'!T$23) -> 0 | U22: =SUM('测算-高个子抖音'!V$23)+SUM('测算-高个子视频号'!V$23)+SUM('测算-天猫淘宝'!V$22)+SUM('测算-拼多多'!V$23)+SUM('测算-京东POP'!V$23)+SUM('测算-达播'!V$24)+SUM('测算-私域'!V$23)+SUM('测算-外部分销'!V$23) -> 0 | V22: =SUM('测算-高个子抖音'!W$23)+SUM('测算-高个子视频号'!W$23)+SUM('测算-天猫淘宝'!W$22)+SUM('测算-拼多多'!W$23)+SUM('测算-京东POP'!W$23)+SUM('测算-达播'!W$24)+SUM('测算-私域'!W$23)+SUM('测算-外部分销'!W$23) -> 0
D23: 分销返佣 | E23: 渠道测算费用明细 | F23: 各渠道测算表汇总 | H23: =SUM('测算-高个子抖音'!I$24)+SUM('测算-高个子视频号'!I$24)+SUM('测算-天猫淘宝'!I$23)+SUM('测算-拼多多'!I$24)+SUM('测算-京东POP'!I$24)+SUM('测算-京东自营'!I$24)+SUM('测算-达播'!I$25)+SUM('测算-私域'!I$24)+SUM('测算-外部分销'!I$24) -> 0 | I23: =SUM('测算-高个子抖音'!J$24)+SUM('测算-高个子视频号'!J$24)+SUM('测算-天猫淘宝'!J$23)+SUM('测算-拼多多'!J$24)+SUM('测算-京东POP'!J$24)+SUM('测算-京东自营'!J$24)+SUM('测算-达播'!J$25)+SUM('测算-私域'!J$24)+SUM('测算-外部分销'!J$24) -> 0 | J23: =SUM('测算-高个子抖音'!K$24)+SUM('测算-高个子视频号'!K$24)+SUM('测算-天猫淘宝'!K$23)+SUM('测算-拼多多'!K$24)+SUM('测算-京东POP'!K$24)+SUM('测算-京东自营'!K$24)+SUM('测算-达播'!K$25)+SUM('测算-私域'!K$24)+SUM('测算-外部分销'!K$24) -> 0 | K23: =SUM('测算-高个子抖音'!L$24)+SUM('测算-高个子视频号'!L$24)+SUM('测算-天猫淘宝'!L$23)+SUM('测算-拼多多'!L$24)+SUM('测算-京东POP'!L$24)+SUM('测算-京东自营'!L$24)+SUM('测算-达播'!L$25)+SUM('测算-私域'!L$24)+SUM('测算-外部分销'!L$24) -> 0 | L23: =SUM('测算-高个子抖音'!M$24)+SUM('测算-高个子视频号'!M$24)+SUM('测算-天猫淘宝'!M$23)+SUM('测算-拼多多'!M$24)+SUM('测算-京东POP'!M$24)+SUM('测算-京东自营'!M$24)+SUM('测算-达播'!M$25)+SUM('测算-私域'!M$24)+SUM('测算-外部分销'!M$24) -> 0 | M23: =SUM('测算-高个子抖音'!N$24)+SUM('测算-高个子视频号'!N$24)+SUM('测算-天猫淘宝'!N$23)+SUM('测算-拼多多'!N$24)+SUM('测算-京东POP'!N$24)+SUM('测算-京东自营'!N$24)+SUM('测算-达播'!N$25)+SUM('测算-私域'!N$24)+SUM('测算-外部分销'!N$24) -> 0 | N23: =SUM('测算-高个子抖音'!O$24)+SUM('测算-高个子视频号'!O$24)+SUM('测算-天猫淘宝'!O$23)+SUM('测算-拼多多'!O$24)+SUM('测算-京东POP'!O$24)+SUM('测算-京东自营'!O$24)+SUM('测算-达播'!O$25)+SUM('测算-私域'!O$24)+SUM('测算-外部分销'!O$24) -> 0 | O23: =SUM('测算-高个子抖音'!P$24)+SUM('测算-高个子视频号'!P$24)+SUM('测算-天猫淘宝'!P$23)+SUM('测算-拼多多'!P$24)+SUM('测算-京东POP'!P$24)+SUM('测算-京东自营'!P$24)+SUM('测算-达播'!P$25)+SUM('测算-私域'!P$24)+SUM('测算-外部分销'!P$24) -> 0 | ... S23: =SUM('测算-高个子抖音'!T$24)+SUM('测算-高个子视频号'!T$24)+SUM('测算-天猫淘宝'!T$23)+SUM('测算-拼多多'!T$24)+SUM('测算-京东POP'!T$24)+SUM('测算-京东自营'!T$24)+SUM('测算-达播'!T$25)+SUM('测算-私域'!T$24)+SUM('测算-外部分销'!T$24) -> 0 | U23: =SUM('测算-高个子抖音'!V$24)+SUM('测算-高个子视频号'!V$24)+SUM('测算-天猫淘宝'!V$23)+SUM('测算-拼多多'!V$24)+SUM('测算-京东POP'!V$24)+SUM('测算-京东自营'!V$24)+SUM('测算-达播'!V$25)+SUM('测算-私域'!V$24)+SUM('测算-外部分销'!V$24) -> 0 | V23: =SUM('测算-高个子抖音'!W$24)+SUM('测算-高个子视频号'!W$24)+SUM('测算-天猫淘宝'!W$23)+SUM('测算-拼多多'!W$24)+SUM('测算-京东POP'!W$24)+SUM('测算-京东自营'!W$24)+SUM('测算-达播'!W$25)+SUM('测算-私域'!W$24)+SUM('测算-外部分销'!W$24) -> 0
D24: 平台毛利补贴 | E24: 渠道测算费用明细 | F24: 各渠道测算表汇总 | H24: =SUM('测算-高个子抖音'!I$25)+SUM('测算-高个子视频号'!I$25)+SUM('测算-天猫淘宝'!I$24)+SUM('测算-拼多多'!I$25)+SUM('测算-京东POP'!I$25)+SUM('测算-京东自营'!I$25)+SUM('测算-达播'!I$26)+SUM('测算-私域'!I$25)+SUM('测算-外部分销'!I$25) -> 37.598827 | I24: =SUM('测算-高个子抖音'!J$25)+SUM('测算-高个子视频号'!J$25)+SUM('测算-天猫淘宝'!J$24)+SUM('测算-拼多多'!J$25)+SUM('测算-京东POP'!J$25)+SUM('测算-京东自营'!J$25)+SUM('测算-达播'!J$26)+SUM('测算-私域'!J$25)+SUM('测算-外部分销'!J$25) -> 19.697303 | J24: =SUM('测算-高个子抖音'!K$25)+SUM('测算-高个子视频号'!K$25)+SUM('测算-天猫淘宝'!K$24)+SUM('测算-拼多多'!K$25)+SUM('测算-京东POP'!K$25)+SUM('测算-京东自营'!K$25)+SUM('测算-达播'!K$26)+SUM('测算-私域'!K$25)+SUM('测算-外部分销'!K$25) -> 33.311613 | K24: =SUM('测算-高个子抖音'!L$25)+SUM('测算-高个子视频号'!L$25)+SUM('测算-天猫淘宝'!L$24)+SUM('测算-拼多多'!L$25)+SUM('测算-京东POP'!L$25)+SUM('测算-京东自营'!L$25)+SUM('测算-达播'!L$26)+SUM('测算-私域'!L$25)+SUM('测算-外部分销'!L$25) -> 20.577461 | L24: =SUM('测算-高个子抖音'!M$25)+SUM('测算-高个子视频号'!M$25)+SUM('测算-天猫淘宝'!M$24)+SUM('测算-拼多多'!M$25)+SUM('测算-京东POP'!M$25)+SUM('测算-京东自营'!M$25)+SUM('测算-达播'!M$26)+SUM('测算-私域'!M$25)+SUM('测算-外部分销'!M$25) -> 16.509449 | M24: =SUM('测算-高个子抖音'!N$25)+SUM('测算-高个子视频号'!N$25)+SUM('测算-天猫淘宝'!N$24)+SUM('测算-拼多多'!N$25)+SUM('测算-京东POP'!N$25)+SUM('测算-京东自营'!N$25)+SUM('测算-达播'!N$26)+SUM('测算-私域'!N$25)+SUM('测算-外部分销'!N$25) -> 51.805845 | N24: =SUM('测算-高个子抖音'!O$25)+SUM('测算-高个子视频号'!O$25)+SUM('测算-天猫淘宝'!O$24)+SUM('测算-拼多多'!O$25)+SUM('测算-京东POP'!O$25)+SUM('测算-京东自营'!O$25)+SUM('测算-达播'!O$26)+SUM('测算-私域'!O$25)+SUM('测算-外部分销'!O$25) -> 25.304162 | O24: =SUM('测算-高个子抖音'!P$25)+SUM('测算-高个子视频号'!P$25)+SUM('测算-天猫淘宝'!P$24)+SUM('测算-拼多多'!P$25)+SUM('测算-京东POP'!P$25)+SUM('测算-京东自营'!P$25)+SUM('测算-达播'!P$26)+SUM('测算-私域'!P$25)+SUM('测算-外部分销'!P$25) -> 33.843015 | ... S24: =SUM('测算-高个子抖音'!T$25)+SUM('测算-高个子视频号'!T$25)+SUM('测算-天猫淘宝'!T$24)+SUM('测算-拼多多'!T$25)+SUM('测算-京东POP'!T$25)+SUM('测算-京东自营'!T$25)+SUM('测算-达播'!T$26)+SUM('测算-私域'!T$25)+SUM('测算-外部分销'!T$25) -> 47.900882 | U24: =SUM('测算-高个子抖音'!V$25)+SUM('测算-高个子视频号'!V$25)+SUM('测算-天猫淘宝'!V$24)+SUM('测算-拼多多'!V$25)+SUM('测算-京东POP'!V$25)+SUM('测算-京东自营'!V$25)+SUM('测算-达播'!V$26)+SUM('测算-私域'!V$25)+SUM('测算-外部分销'!V$25) -> 431.86525 | V24: =SUM('测算-高个子抖音'!W$25)+SUM('测算-高个子视频号'!W$25)+SUM('测算-天猫淘宝'!W$24)+SUM('测算-拼多多'!W$25)+SUM('测算-京东POP'!W$25)+SUM('测算-京东自营'!W$25)+SUM('测算-达播'!W$26)+SUM('测算-私域'!W$25)+SUM('测算-外部分销'!W$25) -> 252.36476
D25: 平台提现手续费 | E25: 渠道测算费用明细 | F25: 各渠道测算表汇总 | H25: =SUM('测算-高个子抖音'!I$26)+SUM('测算-高个子视频号'!I$26)+SUM('测算-天猫淘宝'!I$25)+SUM('测算-拼多多'!I$26)+SUM('测算-京东POP'!I$26)+SUM('测算-京东自营'!I$26)+SUM('测算-达播'!I$27)+SUM('测算-私域'!I$26)+SUM('测算-外部分销'!I$26) -> 30.256177 | I25: =SUM('测算-高个子抖音'!J$26)+SUM('测算-高个子视频号'!J$26)+SUM('测算-天猫淘宝'!J$25)+SUM('测算-拼多多'!J$26)+SUM('测算-京东POP'!J$26)+SUM('测算-京东自营'!J$26)+SUM('测算-达播'!J$27)+SUM('测算-私域'!J$26)+SUM('测算-外部分销'!J$26) -> 8.9596448 | J25: =SUM('测算-高个子抖音'!K$26)+SUM('测算-高个子视频号'!K$26)+SUM('测算-天猫淘宝'!K$25)+SUM('测算-拼多多'!K$26)+SUM('测算-京东POP'!K$26)+SUM('测算-京东自营'!K$26)+SUM('测算-达播'!K$27)+SUM('测算-私域'!K$26)+SUM('测算-外部分销'!K$26) -> 67.951923 | K25: =SUM('测算-高个子抖音'!L$26)+SUM('测算-高个子视频号'!L$26)+SUM('测算-天猫淘宝'!L$25)+SUM('测算-拼多多'!L$26)+SUM('测算-京东POP'!L$26)+SUM('测算-京东自营'!L$26)+SUM('测算-达播'!L$27)+SUM('测算-私域'!L$26)+SUM('测算-外部分销'!L$26) -> 20.928625 | L25: =SUM('测算-高个子抖音'!M$26)+SUM('测算-高个子视频号'!M$26)+SUM('测算-天猫淘宝'!M$25)+SUM('测算-拼多多'!M$26)+SUM('测算-京东POP'!M$26)+SUM('测算-京东自营'!M$26)+SUM('测算-达播'!M$27)+SUM('测算-私域'!M$26)+SUM('测算-外部分销'!M$26) -> 30.271928 | M25: =SUM('测算-高个子抖音'!N$26)+SUM('测算-高个子视频号'!N$26)+SUM('测算-天猫淘宝'!N$25)+SUM('测算-拼多多'!N$26)+SUM('测算-京东POP'!N$26)+SUM('测算-京东自营'!N$26)+SUM('测算-达播'!N$27)+SUM('测算-私域'!N$26)+SUM('测算-外部分销'!N$26) -> 19.206113 | N25: =SUM('测算-高个子抖音'!O$26)+SUM('测算-高个子视频号'!O$26)+SUM('测算-天猫淘宝'!O$25)+SUM('测算-拼多多'!O$26)+SUM('测算-京东POP'!O$26)+SUM('测算-京东自营'!O$26)+SUM('测算-达播'!O$27)+SUM('测算-私域'!O$26)+SUM('测算-外部分销'!O$26) -> 11.059486 | O25: =SUM('测算-高个子抖音'!P$26)+SUM('测算-高个子视频号'!P$26)+SUM('测算-天猫淘宝'!P$25)+SUM('测算-拼多多'!P$26)+SUM('测算-京东POP'!P$26)+SUM('测算-京东自营'!P$26)+SUM('测算-达播'!P$27)+SUM('测算-私域'!P$26)+SUM('测算-外部分销'!P$26) -> 14.791494 | ... S25: =SUM('测算-高个子抖音'!T$26)+SUM('测算-高个子视频号'!T$26)+SUM('测算-天猫淘宝'!T$25)+SUM('测算-拼多多'!T$26)+SUM('测算-京东POP'!T$26)+SUM('测算-京东自营'!T$26)+SUM('测算-达播'!T$27)+SUM('测算-私域'!T$26)+SUM('测算-外部分销'!T$26) -> 20.935653 | U25: =SUM('测算-高个子抖音'!V$26)+SUM('测算-高个子视频号'!V$26)+SUM('测算-天猫淘宝'!V$25)+SUM('测算-拼多多'!V$26)+SUM('测算-京东POP'!V$26)+SUM('测算-京东自营'!V$26)+SUM('测算-达播'!V$27)+SUM('测算-私域'!V$26)+SUM('测算-外部分销'!V$26) -> 287.87344 | V25: =SUM('测算-高个子抖音'!W$26)+SUM('测算-高个子视频号'!W$26)+SUM('测算-天猫淘宝'!W$25)+SUM('测算-拼多多'!W$26)+SUM('测算-京东POP'!W$26)+SUM('测算-京东自营'!W$26)+SUM('测算-达播'!W$27)+SUM('测算-私域'!W$26)+SUM('测算-外部分销'!W$26) -> 110.29903
D26: 自营渠道推广费 | E26: 渠道测算费用明细 | F26: 各渠道测算表汇总 | H26: =SUM('测算-京东自营'!I$22) -> 0.160283 | I26: =SUM('测算-京东自营'!J$22) -> 0.157019 | J26: =SUM('测算-京东自营'!K$22) -> 0.504767 | K26: =SUM('测算-京东自营'!L$22) -> 0.367181 | L26: =SUM('测算-京东自营'!M$22) -> 4.232029 | M26: =SUM('测算-京东自营'!N$22) -> 2.1994182 | N26: =SUM('测算-京东自营'!O$22) -> 1.0742887 | O26: =SUM('测算-京东自营'!P$22) -> 1.4368058 | ... S26: =SUM('测算-京东自营'!T$22) -> 2.0336329 | U26: =SUM('测算-京东自营'!V$22) -> 18.334848 | V26: =SUM('测算-京东自营'!W$22) -> 10.714151
D27: 商务政策费用 | E27: 渠道测算费用明细 | F27: 各渠道测算表汇总 | H27: =SUM('测算-京东自营'!I$23) -> 2.78929 | I27: =SUM('测算-京东自营'!J$23) -> 2.923083 | J27: =SUM('测算-京东自营'!K$23) -> 16.47138 | K27: =SUM('测算-京东自营'!L$23) -> 3.142293 | L27: =SUM('测算-京东自营'!M$23) -> 7.224989 | M27: =SUM('测算-京东自营'!N$23) -> 13.205987 | N27: =SUM('测算-京东自营'!O$23) -> 6.4503613 | O27: =SUM('测算-京东自营'!P$23) -> 8.6270265 | ... S27: =SUM('测算-京东自营'!T$23) -> 12.210561 | U27: =SUM('测算-京东自营'!V$23) -> 110.08809 | V27: =SUM('测算-京东自营'!W$23) -> 64.331073
D28: 退货成本 | E28: 渠道测算费用明细 | F28: 各渠道测算表汇总 | H28: =SUM('测算-京东自营'!I$27) -> 6.38556 | I28: =SUM('测算-京东自营'!J$27) -> 3.46067 | J28: =SUM('测算-京东自营'!K$27) -> 11.14547 | K28: =SUM('测算-京东自营'!L$27) -> 6.25147 | L28: =SUM('测算-京东自营'!M$27) -> 18.65732 | M28: =SUM('测算-京东自营'!N$27) -> 18.621874 | N28: =SUM('测算-京东自营'!O$27) -> 9.0957091 | O28: =SUM('测算-京东自营'!P$27) -> 12.165043 | ... S28: =SUM('测算-京东自营'!T$27) -> 17.218215 | U28: =SUM('测算-京东自营'!V$27) -> 155.23615 | V28: =SUM('测算-京东自营'!W$27) -> 90.71379
C29: 达人费用 | H29: =SUM(H30:H33) -> 0 | I29: =SUM(I30:I33) -> 0 | J29: =SUM(J30:J33) -> 0 | K29: =SUM(K30:K33) -> 0 | L29: =SUM(L30:L33) -> 0 | M29: =SUM(M30:M33) -> 0 | N29: =SUM(N30:N33) -> 22.751163 | O29: =SUM(O30:O33) -> 30.42851 | ... S29: =SUM(S30:S33) -> 43.068044 | U29: =SUM(U30:U33) -> 226.90306 | V29: =SUM(V30:V33) -> 226.90306
D30: 达人视频采买 | E30: 渠道测算费用明细 | F30: 各渠道测算表汇总 | H30: =SUM('测算-高个子抖音'!I$28)+SUM('测算-高个子视频号'!I$28)+SUM('测算-天猫淘宝'!I$27)+SUM('测算-拼多多'!I$28)+SUM('测算-京东POP'!I$28)+SUM('测算-京东自营'!I$29)+SUM('测算-达播'!I$29)+SUM('测算-私域'!I$28)+SUM('测算-外部分销'!I$28) -> 0 | I30: =SUM('测算-高个子抖音'!J$28)+SUM('测算-高个子视频号'!J$28)+SUM('测算-天猫淘宝'!J$27)+SUM('测算-拼多多'!J$28)+SUM('测算-京东POP'!J$28)+SUM('测算-京东自营'!J$29)+SUM('测算-达播'!J$29)+SUM('测算-私域'!J$28)+SUM('测算-外部分销'!J$28) -> 0 | J30: =SUM('测算-高个子抖音'!K$28)+SUM('测算-高个子视频号'!K$28)+SUM('测算-天猫淘宝'!K$27)+SUM('测算-拼多多'!K$28)+SUM('测算-京东POP'!K$28)+SUM('测算-京东自营'!K$29)+SUM('测算-达播'!K$29)+SUM('测算-私域'!K$28)+SUM('测算-外部分销'!K$28) -> 0 | K30: =SUM('测算-高个子抖音'!L$28)+SUM('测算-高个子视频号'!L$28)+SUM('测算-天猫淘宝'!L$27)+SUM('测算-拼多多'!L$28)+SUM('测算-京东POP'!L$28)+SUM('测算-京东自营'!L$29)+SUM('测算-达播'!L$29)+SUM('测算-私域'!L$28)+SUM('测算-外部分销'!L$28) -> 0 | L30: =SUM('测算-高个子抖音'!M$28)+SUM('测算-高个子视频号'!M$28)+SUM('测算-天猫淘宝'!M$27)+SUM('测算-拼多多'!M$28)+SUM('测算-京东POP'!M$28)+SUM('测算-京东自营'!M$29)+SUM('测算-达播'!M$29)+SUM('测算-私域'!M$28)+SUM('测算-外部分销'!M$28) -> 0 | M30: =SUM('测算-高个子抖音'!N$28)+SUM('测算-高个子视频号'!N$28)+SUM('测算-天猫淘宝'!N$27)+SUM('测算-拼多多'!N$28)+SUM('测算-京东POP'!N$28)+SUM('测算-京东自营'!N$29)+SUM('测算-达播'!N$29)+SUM('测算-私域'!N$28)+SUM('测算-外部分销'!N$28) -> 0 | N30: =SUM('测算-高个子抖音'!O$28)+SUM('测算-高个子视频号'!O$28)+SUM('测算-天猫淘宝'!O$27)+SUM('测算-拼多多'!O$28)+SUM('测算-京东POP'!O$28)+SUM('测算-京东自营'!O$29)+SUM('测算-达播'!O$29)+SUM('测算-私域'!O$28)+SUM('测算-外部分销'!O$28) -> 3.4668438 | O30: =SUM('测算-高个子抖音'!P$28)+SUM('测算-高个子视频号'!P$28)+SUM('测算-天猫淘宝'!P$27)+SUM('测算-拼多多'!P$28)+SUM('测算-京东POP'!P$28)+SUM('测算-京东自营'!P$29)+SUM('测算-达播'!P$29)+SUM('测算-私域'!P$28)+SUM('测算-外部分销'!P$28) -> 4.6367253 | ... S30: =SUM('测算-高个子抖音'!T$28)+SUM('测算-高个子视频号'!T$28)+SUM('测算-天猫淘宝'!T$27)+SUM('测算-拼多多'!T$28)+SUM('测算-京东POP'!T$28)+SUM('测算-京东自营'!T$29)+SUM('测算-达播'!T$29)+SUM('测算-私域'!T$28)+SUM('测算-外部分销'!T$28) -> 6.5627496 | U30: =SUM('测算-高个子抖音'!V$28)+SUM('测算-高个子视频号'!V$28)+SUM('测算-天猫淘宝'!V$27)+SUM('测算-拼多多'!V$28)+SUM('测算-京东POP'!V$28)+SUM('测算-京东自营'!V$29)+SUM('测算-达播'!V$29)+SUM('测算-私域'!V$28)+SUM('测算-外部分销'!V$28) -> 34.575704 | V30: =SUM('测算-高个子抖音'!W$28)+SUM('测算-高个子视频号'!W$28)+SUM('测算-天猫淘宝'!W$27)+SUM('测算-拼多多'!W$28)+SUM('测算-京东POP'!W$28)+SUM('测算-京东自营'!W$29)+SUM('测算-达播'!W$29)+SUM('测算-私域'!W$28)+SUM('测算-外部分销'!W$28) -> 34.575704
D31: 达人视频带货佣金 | E31: 渠道测算费用明细 | F31: 各渠道测算表汇总 | H31: =SUM('测算-高个子抖音'!I$29)+SUM('测算-高个子视频号'!I$29)+SUM('测算-天猫淘宝'!I$28)+SUM('测算-拼多多'!I$29)+SUM('测算-京东POP'!I$29)+SUM('测算-京东自营'!I$30)+SUM('测算-达播'!I$30)+SUM('测算-私域'!I$29)+SUM('测算-外部分销'!I$29) -> 0 | I31: =SUM('测算-高个子抖音'!J$29)+SUM('测算-高个子视频号'!J$29)+SUM('测算-天猫淘宝'!J$28)+SUM('测算-拼多多'!J$29)+SUM('测算-京东POP'!J$29)+SUM('测算-京东自营'!J$30)+SUM('测算-达播'!J$30)+SUM('测算-私域'!J$29)+SUM('测算-外部分销'!J$29) -> 0 | J31: =SUM('测算-高个子抖音'!K$29)+SUM('测算-高个子视频号'!K$29)+SUM('测算-天猫淘宝'!K$28)+SUM('测算-拼多多'!K$29)+SUM('测算-京东POP'!K$29)+SUM('测算-京东自营'!K$30)+SUM('测算-达播'!K$30)+SUM('测算-私域'!K$29)+SUM('测算-外部分销'!K$29) -> 0 | K31: =SUM('测算-高个子抖音'!L$29)+SUM('测算-高个子视频号'!L$29)+SUM('测算-天猫淘宝'!L$28)+SUM('测算-拼多多'!L$29)+SUM('测算-京东POP'!L$29)+SUM('测算-京东自营'!L$30)+SUM('测算-达播'!L$30)+SUM('测算-私域'!L$29)+SUM('测算-外部分销'!L$29) -> 0 | L31: =SUM('测算-高个子抖音'!M$29)+SUM('测算-高个子视频号'!M$29)+SUM('测算-天猫淘宝'!M$28)+SUM('测算-拼多多'!M$29)+SUM('测算-京东POP'!M$29)+SUM('测算-京东自营'!M$30)+SUM('测算-达播'!M$30)+SUM('测算-私域'!M$29)+SUM('测算-外部分销'!M$29) -> 0 | M31: =SUM('测算-高个子抖音'!N$29)+SUM('测算-高个子视频号'!N$29)+SUM('测算-天猫淘宝'!N$28)+SUM('测算-拼多多'!N$29)+SUM('测算-京东POP'!N$29)+SUM('测算-京东自营'!N$30)+SUM('测算-达播'!N$30)+SUM('测算-私域'!N$29)+SUM('测算-外部分销'!N$29) -> 0 | N31: =SUM('测算-高个子抖音'!O$29)+SUM('测算-高个子视频号'!O$29)+SUM('测算-天猫淘宝'!O$28)+SUM('测算-拼多多'!O$29)+SUM('测算-京东POP'!O$29)+SUM('测算-京东自营'!O$30)+SUM('测算-达播'!O$30)+SUM('测算-私域'!O$29)+SUM('测算-外部分销'!O$29) -> 5.2002657 | O31: =SUM('测算-高个子抖音'!P$29)+SUM('测算-高个子视频号'!P$29)+SUM('测算-天猫淘宝'!P$28)+SUM('测算-拼多多'!P$29)+SUM('测算-京东POP'!P$29)+SUM('测算-京东自营'!P$30)+SUM('测算-达播'!P$30)+SUM('测算-私域'!P$29)+SUM('测算-外部分销'!P$29) -> 6.9550879 | ... S31: =SUM('测算-高个子抖音'!T$29)+SUM('测算-高个子视频号'!T$29)+SUM('测算-天猫淘宝'!T$28)+SUM('测算-拼多多'!T$29)+SUM('测算-京东POP'!T$29)+SUM('测算-京东自营'!T$30)+SUM('测算-达播'!T$30)+SUM('测算-私域'!T$29)+SUM('测算-外部分销'!T$29) -> 9.8441244 | U31: =SUM('测算-高个子抖音'!V$29)+SUM('测算-高个子视频号'!V$29)+SUM('测算-天猫淘宝'!V$28)+SUM('测算-拼多多'!V$29)+SUM('测算-京东POP'!V$29)+SUM('测算-京东自营'!V$30)+SUM('测算-达播'!V$30)+SUM('测算-私域'!V$29)+SUM('测算-外部分销'!V$29) -> 51.863555 | V31: =SUM('测算-高个子抖音'!W$29)+SUM('测算-高个子视频号'!W$29)+SUM('测算-天猫淘宝'!W$28)+SUM('测算-拼多多'!W$29)+SUM('测算-京东POP'!W$29)+SUM('测算-京东自营'!W$30)+SUM('测算-达播'!W$30)+SUM('测算-私域'!W$29)+SUM('测算-外部分销'!W$29) -> 51.863555
D32: 达人直播带货佣金 | E32: 渠道测算费用明细 | F32: 各渠道测算表汇总 | H32: =SUM('测算-高个子抖音'!I$30)+SUM('测算-高个子视频号'!I$30)+SUM('测算-天猫淘宝'!I$29)+SUM('测算-拼多多'!I$30)+SUM('测算-京东POP'!I$30)+SUM('测算-京东自营'!I$31)+SUM('测算-达播'!I$31)+SUM('测算-私域'!I$30)+SUM('测算-外部分销'!I$30) -> 0 | I32: =SUM('测算-高个子抖音'!J$30)+SUM('测算-高个子视频号'!J$30)+SUM('测算-天猫淘宝'!J$29)+SUM('测算-拼多多'!J$30)+SUM('测算-京东POP'!J$30)+SUM('测算-京东自营'!J$31)+SUM('测算-达播'!J$31)+SUM('测算-私域'!J$30)+SUM('测算-外部分销'!J$30) -> 0 | J32: =SUM('测算-高个子抖音'!K$30)+SUM('测算-高个子视频号'!K$30)+SUM('测算-天猫淘宝'!K$29)+SUM('测算-拼多多'!K$30)+SUM('测算-京东POP'!K$30)+SUM('测算-京东自营'!K$31)+SUM('测算-达播'!K$31)+SUM('测算-私域'!K$30)+SUM('测算-外部分销'!K$30) -> 0 | K32: =SUM('测算-高个子抖音'!L$30)+SUM('测算-高个子视频号'!L$30)+SUM('测算-天猫淘宝'!L$29)+SUM('测算-拼多多'!L$30)+SUM('测算-京东POP'!L$30)+SUM('测算-京东自营'!L$31)+SUM('测算-达播'!L$31)+SUM('测算-私域'!L$30)+SUM('测算-外部分销'!L$30) -> 0 | L32: =SUM('测算-高个子抖音'!M$30)+SUM('测算-高个子视频号'!M$30)+SUM('测算-天猫淘宝'!M$29)+SUM('测算-拼多多'!M$30)+SUM('测算-京东POP'!M$30)+SUM('测算-京东自营'!M$31)+SUM('测算-达播'!M$31)+SUM('测算-私域'!M$30)+SUM('测算-外部分销'!M$30) -> 0 | M32: =SUM('测算-高个子抖音'!N$30)+SUM('测算-高个子视频号'!N$30)+SUM('测算-天猫淘宝'!N$29)+SUM('测算-拼多多'!N$30)+SUM('测算-京东POP'!N$30)+SUM('测算-京东自营'!N$31)+SUM('测算-达播'!N$31)+SUM('测算-私域'!N$30)+SUM('测算-外部分销'!N$30) -> 0 | N32: =SUM('测算-高个子抖音'!O$30)+SUM('测算-高个子视频号'!O$30)+SUM('测算-天猫淘宝'!O$29)+SUM('测算-拼多多'!O$30)+SUM('测算-京东POP'!O$30)+SUM('测算-京东自营'!O$31)+SUM('测算-达播'!O$31)+SUM('测算-私域'!O$30)+SUM('测算-外部分销'!O$30) -> 6.2836544 | O32: =SUM('测算-高个子抖音'!P$30)+SUM('测算-高个子视频号'!P$30)+SUM('测算-天猫淘宝'!P$29)+SUM('测算-拼多多'!P$30)+SUM('测算-京东POP'!P$30)+SUM('测算-京东自营'!P$31)+SUM('测算-达播'!P$31)+SUM('测算-私域'!P$30)+SUM('测算-外部分销'!P$30) -> 8.4040646 | ... S32: =SUM('测算-高个子抖音'!T$30)+SUM('测算-高个子视频号'!T$30)+SUM('测算-天猫淘宝'!T$29)+SUM('测算-拼多多'!T$30)+SUM('测算-京东POP'!T$30)+SUM('测算-京东自营'!T$31)+SUM('测算-达播'!T$31)+SUM('测算-私域'!T$30)+SUM('测算-外部分销'!T$30) -> 11.894984 | U32: =SUM('测算-高个子抖音'!V$30)+SUM('测算-高个子视频号'!V$30)+SUM('测算-天猫淘宝'!V$29)+SUM('测算-拼多多'!V$30)+SUM('测算-京东POP'!V$30)+SUM('测算-京东自营'!V$31)+SUM('测算-达播'!V$31)+SUM('测算-私域'!V$30)+SUM('测算-外部分销'!V$30) -> 62.668463 | V32: =SUM('测算-高个子抖音'!W$30)+SUM('测算-高个子视频号'!W$30)+SUM('测算-天猫淘宝'!W$29)+SUM('测算-拼多多'!W$30)+SUM('测算-京东POP'!W$30)+SUM('测算-京东自营'!W$31)+SUM('测算-达播'!W$31)+SUM('测算-私域'!W$30)+SUM('测算-外部分销'!W$30) -> 62.668463
D33: 达人直播坑位费 | E33: 渠道测算费用明细 | F33: 各渠道测算表汇总 | H33: =SUM('测算-高个子抖音'!I$31)+SUM('测算-高个子视频号'!I$31)+SUM('测算-天猫淘宝'!I$30)+SUM('测算-拼多多'!I$31)+SUM('测算-京东POP'!I$31)+SUM('测算-京东自营'!I$32)+SUM('测算-达播'!I$32)+SUM('测算-私域'!I$31)+SUM('测算-外部分销'!I$31) -> 0 | I33: =SUM('测算-高个子抖音'!J$31)+SUM('测算-高个子视频号'!J$31)+SUM('测算-天猫淘宝'!J$30)+SUM('测算-拼多多'!J$31)+SUM('测算-京东POP'!J$31)+SUM('测算-京东自营'!J$32)+SUM('测算-达播'!J$32)+SUM('测算-私域'!J$31)+SUM('测算-外部分销'!J$31) -> 0 | J33: =SUM('测算-高个子抖音'!K$31)+SUM('测算-高个子视频号'!K$31)+SUM('测算-天猫淘宝'!K$30)+SUM('测算-拼多多'!K$31)+SUM('测算-京东POP'!K$31)+SUM('测算-京东自营'!K$32)+SUM('测算-达播'!K$32)+SUM('测算-私域'!K$31)+SUM('测算-外部分销'!K$31) -> 0 | K33: =SUM('测算-高个子抖音'!L$31)+SUM('测算-高个子视频号'!L$31)+SUM('测算-天猫淘宝'!L$30)+SUM('测算-拼多多'!L$31)+SUM('测算-京东POP'!L$31)+SUM('测算-京东自营'!L$32)+SUM('测算-达播'!L$32)+SUM('测算-私域'!L$31)+SUM('测算-外部分销'!L$31) -> 0 | L33: =SUM('测算-高个子抖音'!M$31)+SUM('测算-高个子视频号'!M$31)+SUM('测算-天猫淘宝'!M$30)+SUM('测算-拼多多'!M$31)+SUM('测算-京东POP'!M$31)+SUM('测算-京东自营'!M$32)+SUM('测算-达播'!M$32)+SUM('测算-私域'!M$31)+SUM('测算-外部分销'!M$31) -> 0 | M33: =SUM('测算-高个子抖音'!N$31)+SUM('测算-高个子视频号'!N$31)+SUM('测算-天猫淘宝'!N$30)+SUM('测算-拼多多'!N$31)+SUM('测算-京东POP'!N$31)+SUM('测算-京东自营'!N$32)+SUM('测算-达播'!N$32)+SUM('测算-私域'!N$31)+SUM('测算-外部分销'!N$31) -> 0 | N33: =SUM('测算-高个子抖音'!O$31)+SUM('测算-高个子视频号'!O$31)+SUM('测算-天猫淘宝'!O$30)+SUM('测算-拼多多'!O$31)+SUM('测算-京东POP'!O$31)+SUM('测算-京东自营'!O$32)+SUM('测算-达播'!O$32)+SUM('测算-私域'!O$31)+SUM('测算-外部分销'!O$31) -> 7.8003986 | O33: =SUM('测算-高个子抖音'!P$31)+SUM('测算-高个子视频号'!P$31)+SUM('测算-天猫淘宝'!P$30)+SUM('测算-拼多多'!P$31)+SUM('测算-京东POP'!P$31)+SUM('测算-京东自营'!P$32)+SUM('测算-达播'!P$32)+SUM('测算-私域'!P$31)+SUM('测算-外部分销'!P$31) -> 10.432632 | ... S33: =SUM('测算-高个子抖音'!T$31)+SUM('测算-高个子视频号'!T$31)+SUM('测算-天猫淘宝'!T$30)+SUM('测算-拼多多'!T$31)+SUM('测算-京东POP'!T$31)+SUM('测算-京东自营'!T$32)+SUM('测算-达播'!T$32)+SUM('测算-私域'!T$31)+SUM('测算-外部分销'!T$31) -> 14.766187 | U33: =SUM('测算-高个子抖音'!V$31)+SUM('测算-高个子视频号'!V$31)+SUM('测算-天猫淘宝'!V$30)+SUM('测算-拼多多'!V$31)+SUM('测算-京东POP'!V$31)+SUM('测算-京东自营'!V$32)+SUM('测算-达播'!V$32)+SUM('测算-私域'!V$31)+SUM('测算-外部分销'!V$31) -> 77.795333 | V33: =SUM('测算-高个子抖音'!W$31)+SUM('测算-高个子视频号'!W$31)+SUM('测算-天猫淘宝'!W$30)+SUM('测算-拼多多'!W$31)+SUM('测算-京东POP'!W$31)+SUM('测算-京东自营'!W$32)+SUM('测算-达播'!W$32)+SUM('测算-私域'!W$31)+SUM('测算-外部分销'!W$31) -> 77.795333
C34: 行销支持 | H34: =SUM(H35:H37) -> 7.659842 | I34: =SUM(I35:I37) -> 3.539312 | J34: =SUM(J35:J37) -> 7.686161 | K34: =SUM(K35:K37) -> 4.708707 | L34: =SUM(L35:L37) -> 8.107537 | M34: =SUM(M35:M37) -> 11.194122 | N34: =SUM(N35:N37) -> 7.5643179 | O34: =SUM(O35:O37) -> 9.6528241 | ... S34: =SUM(S35:S37) -> 13.082199 | U34: =SUM(U35:U37) -> 112.8851 | V34: =SUM(V35:V37) -> 69.989414
D35: 促销物料 | E35: 渠道测算费用明细 | F35: 各渠道测算表汇总 | H35: =SUM('测算-高个子抖音'!I$33)+SUM('测算-高个子视频号'!I$33)+SUM('测算-天猫淘宝'!I$32)+SUM('测算-拼多多'!I$33)+SUM('测算-京东POP'!I$33)+SUM('测算-京东自营'!I$34)+SUM('测算-达播'!I$34)+SUM('测算-私域'!I$33)+SUM('测算-外部分销'!I$33) -> 3.887473 | I35: =SUM('测算-高个子抖音'!J$33)+SUM('测算-高个子视频号'!J$33)+SUM('测算-天猫淘宝'!J$32)+SUM('测算-拼多多'!J$33)+SUM('测算-京东POP'!J$33)+SUM('测算-京东自营'!J$34)+SUM('测算-达播'!J$34)+SUM('测算-私域'!J$33)+SUM('测算-外部分销'!J$33) -> 0.870303 | J35: =SUM('测算-高个子抖音'!K$33)+SUM('测算-高个子视频号'!K$33)+SUM('测算-天猫淘宝'!K$32)+SUM('测算-拼多多'!K$33)+SUM('测算-京东POP'!K$33)+SUM('测算-京东自营'!K$34)+SUM('测算-达播'!K$34)+SUM('测算-私域'!K$33)+SUM('测算-外部分销'!K$33) -> 2.244855 | K35: =SUM('测算-高个子抖音'!L$33)+SUM('测算-高个子视频号'!L$33)+SUM('测算-天猫淘宝'!L$32)+SUM('测算-拼多多'!L$33)+SUM('测算-京东POP'!L$33)+SUM('测算-京东自营'!L$34)+SUM('测算-达播'!L$34)+SUM('测算-私域'!L$33)+SUM('测算-外部分销'!L$33) -> 0.384608 | L35: =SUM('测算-高个子抖音'!M$33)+SUM('测算-高个子视频号'!M$33)+SUM('测算-天猫淘宝'!M$32)+SUM('测算-拼多多'!M$33)+SUM('测算-京东POP'!M$33)+SUM('测算-京东自营'!M$34)+SUM('测算-达播'!M$34)+SUM('测算-私域'!M$33)+SUM('测算-外部分销'!M$33) -> 3.535826 | M35: =SUM('测算-高个子抖音'!N$33)+SUM('测算-高个子视频号'!N$33)+SUM('测算-天猫淘宝'!N$32)+SUM('测算-拼多多'!N$33)+SUM('测算-京东POP'!N$33)+SUM('测算-京东自营'!N$34)+SUM('测算-达播'!N$34)+SUM('测算-私域'!N$33)+SUM('测算-外部分销'!N$33) -> 6.3484551 | N35: =SUM('测算-高个子抖音'!O$33)+SUM('测算-高个子视频号'!O$33)+SUM('测算-天猫淘宝'!O$32)+SUM('测算-拼多多'!O$33)+SUM('测算-京东POP'!O$33)+SUM('测算-京东自营'!O$34)+SUM('测算-达播'!O$34)+SUM('测算-私域'!O$33)+SUM('测算-外部分销'!O$33) -> 4.7589797 | O35: =SUM('测算-高个子抖音'!P$33)+SUM('测算-高个子视频号'!P$33)+SUM('测算-天猫淘宝'!P$32)+SUM('测算-拼多多'!P$33)+SUM('测算-京东POP'!P$33)+SUM('测算-京东自营'!P$34)+SUM('测算-达播'!P$34)+SUM('测算-私域'!P$33)+SUM('测算-外部分销'!P$33) -> 6.3648906 | ... S35: =SUM('测算-高个子抖音'!T$33)+SUM('测算-高个子视频号'!T$33)+SUM('测算-天猫淘宝'!T$32)+SUM('测算-拼多多'!T$33)+SUM('测算-京东POP'!T$33)+SUM('测算-京东自营'!T$34)+SUM('测算-达播'!T$34)+SUM('测算-私域'!T$33)+SUM('测算-外部分销'!T$33) -> 9.0087682 | U35: =SUM('测算-高个子抖音'!V$33)+SUM('测算-高个子视频号'!V$33)+SUM('测算-天猫淘宝'!V$32)+SUM('测算-拼多多'!V$33)+SUM('测算-京东POP'!V$33)+SUM('测算-京东自营'!V$34)+SUM('测算-达播'!V$34)+SUM('测算-私域'!V$33)+SUM('测算-外部分销'!V$33) -> 64.73402 | V35: =SUM('测算-高个子抖音'!W$33)+SUM('测算-高个子视频号'!W$33)+SUM('测算-天猫淘宝'!W$32)+SUM('测算-拼多多'!W$33)+SUM('测算-京东POP'!W$33)+SUM('测算-京东自营'!W$34)+SUM('测算-达播'!W$34)+SUM('测算-私域'!W$33)+SUM('测算-外部分销'!W$33) -> 47.4625
D36: 赠饮样品费 | E36: 渠道测算费用明细 | F36: 各渠道测算表汇总 | H36: =SUM('测算-高个子抖音'!I$34)+SUM('测算-高个子视频号'!I$34)+SUM('测算-天猫淘宝'!I$33)+SUM('测算-拼多多'!I$34)+SUM('测算-京东POP'!I$34)+SUM('测算-京东自营'!I$35)+SUM('测算-达播'!I$35)+SUM('测算-私域'!I$34)+SUM('测算-外部分销'!I$34) -> 0 | I36: =SUM('测算-高个子抖音'!J$34)+SUM('测算-高个子视频号'!J$34)+SUM('测算-天猫淘宝'!J$33)+SUM('测算-拼多多'!J$34)+SUM('测算-京东POP'!J$34)+SUM('测算-京东自营'!J$35)+SUM('测算-达播'!J$35)+SUM('测算-私域'!J$34)+SUM('测算-外部分销'!J$34) -> 0 | J36: =SUM('测算-高个子抖音'!K$34)+SUM('测算-高个子视频号'!K$34)+SUM('测算-天猫淘宝'!K$33)+SUM('测算-拼多多'!K$34)+SUM('测算-京东POP'!K$34)+SUM('测算-京东自营'!K$35)+SUM('测算-达播'!K$35)+SUM('测算-私域'!K$34)+SUM('测算-外部分销'!K$34) -> 0 | K36: =SUM('测算-高个子抖音'!L$34)+SUM('测算-高个子视频号'!L$34)+SUM('测算-天猫淘宝'!L$33)+SUM('测算-拼多多'!L$34)+SUM('测算-京东POP'!L$34)+SUM('测算-京东自营'!L$35)+SUM('测算-达播'!L$35)+SUM('测算-私域'!L$34)+SUM('测算-外部分销'!L$34) -> 0 | L36: =SUM('测算-高个子抖音'!M$34)+SUM('测算-高个子视频号'!M$34)+SUM('测算-天猫淘宝'!M$33)+SUM('测算-拼多多'!M$34)+SUM('测算-京东POP'!M$34)+SUM('测算-京东自营'!M$35)+SUM('测算-达播'!M$35)+SUM('测算-私域'!M$34)+SUM('测算-外部分销'!M$34) -> 0 | M36: =SUM('测算-高个子抖音'!N$34)+SUM('测算-高个子视频号'!N$34)+SUM('测算-天猫淘宝'!N$33)+SUM('测算-拼多多'!N$34)+SUM('测算-京东POP'!N$34)+SUM('测算-京东自营'!N$35)+SUM('测算-达播'!N$35)+SUM('测算-私域'!N$34)+SUM('测算-外部分销'!N$34) -> 0 | N36: =SUM('测算-高个子抖音'!O$34)+SUM('测算-高个子视频号'!O$34)+SUM('测算-天猫淘宝'!O$33)+SUM('测算-拼多多'!O$34)+SUM('测算-京东POP'!O$34)+SUM('测算-京东自营'!O$35)+SUM('测算-达播'!O$35)+SUM('测算-私域'!O$34)+SUM('测算-外部分销'!O$34) -> 0 | O36: =SUM('测算-高个子抖音'!P$34)+SUM('测算-高个子视频号'!P$34)+SUM('测算-天猫淘宝'!P$33)+SUM('测算-拼多多'!P$34)+SUM('测算-京东POP'!P$34)+SUM('测算-京东自营'!P$35)+SUM('测算-达播'!P$35)+SUM('测算-私域'!P$34)+SUM('测算-外部分销'!P$34) -> 0 | ... S36: =SUM('测算-高个子抖音'!T$34)+SUM('测算-高个子视频号'!T$34)+SUM('测算-天猫淘宝'!T$33)+SUM('测算-拼多多'!T$34)+SUM('测算-京东POP'!T$34)+SUM('测算-京东自营'!T$35)+SUM('测算-达播'!T$35)+SUM('测算-私域'!T$34)+SUM('测算-外部分销'!T$34) -> 0 | U36: =SUM('测算-高个子抖音'!V$34)+SUM('测算-高个子视频号'!V$34)+SUM('测算-天猫淘宝'!V$33)+SUM('测算-拼多多'!V$34)+SUM('测算-京东POP'!V$34)+SUM('测算-京东自营'!V$35)+SUM('测算-达播'!V$35)+SUM('测算-私域'!V$34)+SUM('测算-外部分销'!V$34) -> 0 | V36: =SUM('测算-高个子抖音'!W$34)+SUM('测算-高个子视频号'!W$34)+SUM('测算-天猫淘宝'!W$33)+SUM('测算-拼多多'!W$34)+SUM('测算-京东POP'!W$34)+SUM('测算-京东自营'!W$35)+SUM('测算-达播'!W$35)+SUM('测算-私域'!W$34)+SUM('测算-外部分销'!W$34) -> 0
D37: 赠品成本 | E37: 渠道测算费用明细 | F37: 各渠道测算表汇总 | H37: =SUM('测算-高个子抖音'!I$35)+SUM('测算-高个子视频号'!I$35)+SUM('测算-天猫淘宝'!I$34)+SUM('测算-拼多多'!I$35)+SUM('测算-京东POP'!I$35)+SUM('测算-京东自营'!I$36)+SUM('测算-达播'!I$36)+SUM('测算-私域'!I$35)+SUM('测算-外部分销'!I$35) -> 3.772369 | I37: =SUM('测算-高个子抖音'!J$35)+SUM('测算-高个子视频号'!J$35)+SUM('测算-天猫淘宝'!J$34)+SUM('测算-拼多多'!J$35)+SUM('测算-京东POP'!J$35)+SUM('测算-京东自营'!J$36)+SUM('测算-达播'!J$36)+SUM('测算-私域'!J$35)+SUM('测算-外部分销'!J$35) -> 2.669009 | J37: =SUM('测算-高个子抖音'!K$35)+SUM('测算-高个子视频号'!K$35)+SUM('测算-天猫淘宝'!K$34)+SUM('测算-拼多多'!K$35)+SUM('测算-京东POP'!K$35)+SUM('测算-京东自营'!K$36)+SUM('测算-达播'!K$36)+SUM('测算-私域'!K$35)+SUM('测算-外部分销'!K$35) -> 5.441306 | K37: =SUM('测算-高个子抖音'!L$35)+SUM('测算-高个子视频号'!L$35)+SUM('测算-天猫淘宝'!L$34)+SUM('测算-拼多多'!L$35)+SUM('测算-京东POP'!L$35)+SUM('测算-京东自营'!L$36)+SUM('测算-达播'!L$36)+SUM('测算-私域'!L$35)+SUM('测算-外部分销'!L$35) -> 4.324099 | L37: =SUM('测算-高个子抖音'!M$35)+SUM('测算-高个子视频号'!M$35)+SUM('测算-天猫淘宝'!M$34)+SUM('测算-拼多多'!M$35)+SUM('测算-京东POP'!M$35)+SUM('测算-京东自营'!M$36)+SUM('测算-达播'!M$36)+SUM('测算-私域'!M$35)+SUM('测算-外部分销'!M$35) -> 4.571711 | M37: =SUM('测算-高个子抖音'!N$35)+SUM('测算-高个子视频号'!N$35)+SUM('测算-天猫淘宝'!N$34)+SUM('测算-拼多多'!N$35)+SUM('测算-京东POP'!N$35)+SUM('测算-京东自营'!N$36)+SUM('测算-达播'!N$36)+SUM('测算-私域'!N$35)+SUM('测算-外部分销'!N$35) -> 4.845667 | N37: =SUM('测算-高个子抖音'!O$35)+SUM('测算-高个子视频号'!O$35)+SUM('测算-天猫淘宝'!O$34)+SUM('测算-拼多多'!O$35)+SUM('测算-京东POP'!O$35)+SUM('测算-京东自营'!O$36)+SUM('测算-达播'!O$36)+SUM('测算-私域'!O$35)+SUM('测算-外部分销'!O$35) -> 2.8053382 | O37: =SUM('测算-高个子抖音'!P$35)+SUM('测算-高个子视频号'!P$35)+SUM('测算-天猫淘宝'!P$34)+SUM('测算-拼多多'!P$35)+SUM('测算-京东POP'!P$35)+SUM('测算-京东自营'!P$36)+SUM('测算-达播'!P$36)+SUM('测算-私域'!P$35)+SUM('测算-外部分销'!P$35) -> 3.2879335 | ... S37: =SUM('测算-高个子抖音'!T$35)+SUM('测算-高个子视频号'!T$35)+SUM('测算-天猫淘宝'!T$34)+SUM('测算-拼多多'!T$35)+SUM('测算-京东POP'!T$35)+SUM('测算-京东自营'!T$36)+SUM('测算-达播'!T$36)+SUM('测算-私域'!T$35)+SUM('测算-外部分销'!T$35) -> 4.0734305 | U37: =SUM('测算-高个子抖音'!V$35)+SUM('测算-高个子视频号'!V$35)+SUM('测算-天猫淘宝'!V$34)+SUM('测算-拼多多'!V$35)+SUM('测算-京东POP'!V$35)+SUM('测算-京东自营'!V$36)+SUM('测算-达播'!V$36)+SUM('测算-私域'!V$35)+SUM('测算-外部分销'!V$35) -> 48.151076 | V37: =SUM('测算-高个子抖音'!W$35)+SUM('测算-高个子视频号'!W$35)+SUM('测算-天猫淘宝'!W$34)+SUM('测算-拼多多'!W$35)+SUM('测算-京东POP'!W$35)+SUM('测算-京东自营'!W$36)+SUM('测算-达播'!W$36)+SUM('测算-私域'!W$35)+SUM('测算-外部分销'!W$35) -> 22.526915
C38: 仓储物流 | H38: =SUM(H39:H42) -> 28.549916 | I38: =SUM(I39:I42) -> 21.185805 | J38: =SUM(J39:J42) -> 40.113545 | K38: =SUM(K39:K42) -> 29.593612 | L38: =SUM(L39:L42) -> 35.070613 | M38: =SUM(M39:M42) -> 48.212656 | N38: =SUM(N39:N42) -> 30.707836 | O38: =SUM(O39:O42) -> 40.606089 | ... S38: =SUM(S39:S42) -> 56.892974 | U38: =SUM(U39:U42) -> 531.62114 | V38: =SUM(V39:V42) -> 300.80553
D39: 快递费用 | E39: 渠道测算费用明细 | F39: 各渠道测算表汇总 | H39: =SUM('测算-高个子抖音'!I$37)+SUM('测算-高个子视频号'!I$37)+SUM('测算-天猫淘宝'!I$36)+SUM('测算-拼多多'!I$37)+SUM('测算-京东POP'!I$37)+SUM('测算-京东自营'!I$38)+SUM('测算-达播'!I$38)+SUM('测算-私域'!I$37)+SUM('测算-外部分销'!I$37) -> 12.31197 | I39: =SUM('测算-高个子抖音'!J$37)+SUM('测算-高个子视频号'!J$37)+SUM('测算-天猫淘宝'!J$36)+SUM('测算-拼多多'!J$37)+SUM('测算-京东POP'!J$37)+SUM('测算-京东自营'!J$38)+SUM('测算-达播'!J$38)+SUM('测算-私域'!J$37)+SUM('测算-外部分销'!J$37) -> 8.740675 | J39: =SUM('测算-高个子抖音'!K$37)+SUM('测算-高个子视频号'!K$37)+SUM('测算-天猫淘宝'!K$36)+SUM('测算-拼多多'!K$37)+SUM('测算-京东POP'!K$37)+SUM('测算-京东自营'!K$38)+SUM('测算-达播'!K$38)+SUM('测算-私域'!K$37)+SUM('测算-外部分销'!K$37) -> 19.75802 | K39: =SUM('测算-高个子抖音'!L$37)+SUM('测算-高个子视频号'!L$37)+SUM('测算-天猫淘宝'!L$36)+SUM('测算-拼多多'!L$37)+SUM('测算-京东POP'!L$37)+SUM('测算-京东自营'!L$38)+SUM('测算-达播'!L$38)+SUM('测算-私域'!L$37)+SUM('测算-外部分销'!L$37) -> 10.679434 | L39: =SUM('测算-高个子抖音'!M$37)+SUM('测算-高个子视频号'!M$37)+SUM('测算-天猫淘宝'!M$36)+SUM('测算-拼多多'!M$37)+SUM('测算-京东POP'!M$37)+SUM('测算-京东自营'!M$38)+SUM('测算-达播'!M$38)+SUM('测算-私域'!M$37)+SUM('测算-外部分销'!M$37) -> 13.419053 | M39: =SUM('测算-高个子抖音'!N$37)+SUM('测算-高个子视频号'!N$37)+SUM('测算-天猫淘宝'!N$36)+SUM('测算-拼多多'!N$37)+SUM('测算-京东POP'!N$37)+SUM('测算-京东自营'!N$38)+SUM('测算-达播'!N$38)+SUM('测算-私域'!N$37)+SUM('测算-外部分销'!N$37) -> 12.024452 | N39: =SUM('测算-高个子抖音'!O$37)+SUM('测算-高个子视频号'!O$37)+SUM('测算-天猫淘宝'!O$36)+SUM('测算-拼多多'!O$37)+SUM('测算-京东POP'!O$37)+SUM('测算-京东自营'!O$38)+SUM('测算-达播'!O$38)+SUM('测算-私域'!O$37)+SUM('测算-外部分销'!O$37) -> 8.9886617 | O39: =SUM('测算-高个子抖音'!P$37)+SUM('测算-高个子视频号'!P$37)+SUM('测算-天猫淘宝'!P$36)+SUM('测算-拼多多'!P$37)+SUM('测算-京东POP'!P$37)+SUM('测算-京东自营'!P$38)+SUM('测算-达播'!P$38)+SUM('测算-私域'!P$37)+SUM('测算-外部分销'!P$37) -> 12.021873 | ... S39: =SUM('测算-高个子抖音'!T$37)+SUM('测算-高个子视频号'!T$37)+SUM('测算-天猫淘宝'!T$36)+SUM('测算-拼多多'!T$37)+SUM('测算-京东POP'!T$37)+SUM('测算-京东自营'!T$38)+SUM('测算-达播'!T$38)+SUM('测算-私域'!T$37)+SUM('测算-外部分销'!T$37) -> 17.015574 | U39: =SUM('测算-高个子抖音'!V$37)+SUM('测算-高个子视频号'!V$37)+SUM('测算-天猫淘宝'!V$36)+SUM('测算-拼多多'!V$37)+SUM('测算-京东POP'!V$37)+SUM('测算-京东自营'!V$38)+SUM('测算-达播'!V$38)+SUM('测算-私域'!V$37)+SUM('测算-外部分销'!V$37) -> 166.57978 | V39: =SUM('测算-高个子抖音'!W$37)+SUM('测算-高个子视频号'!W$37)+SUM('测算-天猫淘宝'!W$36)+SUM('测算-拼多多'!W$37)+SUM('测算-京东POP'!W$37)+SUM('测算-京东自营'!W$38)+SUM('测算-达播'!W$38)+SUM('测算-私域'!W$37)+SUM('测算-外部分销'!W$37) -> 89.64618
D40: 打包包装 | E40: 渠道测算费用明细 | F40: 各渠道测算表汇总 | H40: =SUM('测算-高个子抖音'!I$38)+SUM('测算-高个子视频号'!I$38)+SUM('测算-天猫淘宝'!I$37)+SUM('测算-拼多多'!I$38)+SUM('测算-京东POP'!I$38)+SUM('测算-京东自营'!I$39)+SUM('测算-达播'!I$39)+SUM('测算-私域'!I$38)+SUM('测算-外部分销'!I$38) -> 6.7513262 | I40: =SUM('测算-高个子抖音'!J$38)+SUM('测算-高个子视频号'!J$38)+SUM('测算-天猫淘宝'!J$37)+SUM('测算-拼多多'!J$38)+SUM('测算-京东POP'!J$38)+SUM('测算-京东自营'!J$39)+SUM('测算-达播'!J$39)+SUM('测算-私域'!J$38)+SUM('测算-外部分销'!J$38) -> 3.628259 | J40: =SUM('测算-高个子抖音'!K$38)+SUM('测算-高个子视频号'!K$38)+SUM('测算-天猫淘宝'!K$37)+SUM('测算-拼多多'!K$38)+SUM('测算-京东POP'!K$38)+SUM('测算-京东自营'!K$39)+SUM('测算-达播'!K$39)+SUM('测算-私域'!K$38)+SUM('测算-外部分销'!K$38) -> 8.724739 | K40: =SUM('测算-高个子抖音'!L$38)+SUM('测算-高个子视频号'!L$38)+SUM('测算-天猫淘宝'!L$37)+SUM('测算-拼多多'!L$38)+SUM('测算-京东POP'!L$38)+SUM('测算-京东自营'!L$39)+SUM('测算-达播'!L$39)+SUM('测算-私域'!L$38)+SUM('测算-外部分销'!L$38) -> 4.871998 | L40: =SUM('测算-高个子抖音'!M$38)+SUM('测算-高个子视频号'!M$38)+SUM('测算-天猫淘宝'!M$37)+SUM('测算-拼多多'!M$38)+SUM('测算-京东POP'!M$38)+SUM('测算-京东自营'!M$39)+SUM('测算-达播'!M$39)+SUM('测算-私域'!M$38)+SUM('测算-外部分销'!M$38) -> 6.92985 | M40: =SUM('测算-高个子抖音'!N$38)+SUM('测算-高个子视频号'!N$38)+SUM('测算-天猫淘宝'!N$37)+SUM('测算-拼多多'!N$38)+SUM('测算-京东POP'!N$38)+SUM('测算-京东自营'!N$39)+SUM('测算-达播'!N$39)+SUM('测算-私域'!N$38)+SUM('测算-外部分销'!N$38) -> 6.7076752 | N40: =SUM('测算-高个子抖音'!O$38)+SUM('测算-高个子视频号'!O$38)+SUM('测算-天猫淘宝'!O$37)+SUM('测算-拼多多'!O$38)+SUM('测算-京东POP'!O$38)+SUM('测算-京东自营'!O$39)+SUM('测算-达播'!O$39)+SUM('测算-私域'!O$38)+SUM('测算-外部分销'!O$38) -> 4.2279308 | O40: =SUM('测算-高个子抖音'!P$38)+SUM('测算-高个子视频号'!P$38)+SUM('测算-天猫淘宝'!P$37)+SUM('测算-拼多多'!P$38)+SUM('测算-京东POP'!P$38)+SUM('测算-京东自营'!P$39)+SUM('测算-达播'!P$39)+SUM('测算-私域'!P$38)+SUM('测算-外部分销'!P$38) -> 5.6546399 | ... S40: =SUM('测算-高个子抖音'!T$38)+SUM('测算-高个子视频号'!T$38)+SUM('测算-天猫淘宝'!T$37)+SUM('测算-拼多多'!T$38)+SUM('测算-京东POP'!T$38)+SUM('测算-京东自营'!T$39)+SUM('测算-达播'!T$39)+SUM('测算-私域'!T$38)+SUM('测算-外部分销'!T$38) -> 8.0034904 | U40: =SUM('测算-高个子抖音'!V$38)+SUM('测算-高个子视频号'!V$38)+SUM('测算-天猫淘宝'!V$37)+SUM('测算-拼多多'!V$38)+SUM('测算-京东POP'!V$38)+SUM('测算-京东自营'!V$39)+SUM('测算-达播'!V$39)+SUM('测算-私域'!V$38)+SUM('测算-外部分销'!V$38) -> 79.780062 | V40: =SUM('测算-高个子抖音'!W$38)+SUM('测算-高个子视频号'!W$38)+SUM('测算-天猫淘宝'!W$37)+SUM('测算-拼多多'!W$38)+SUM('测算-京东POP'!W$38)+SUM('测算-京东自营'!W$39)+SUM('测算-达播'!W$39)+SUM('测算-私域'!W$38)+SUM('测算-外部分销'!W$38) -> 42.166215
D41: 干线费用 | E41: 渠道测算费用明细 | F41: 各渠道测算表汇总 | H41: =SUM('测算-高个子抖音'!I$39)+SUM('测算-高个子视频号'!I$39)+SUM('测算-天猫淘宝'!I$38)+SUM('测算-拼多多'!I$39)+SUM('测算-京东POP'!I$39)+SUM('测算-京东自营'!I$40)+SUM('测算-达播'!I$40)+SUM('测算-私域'!I$39)+SUM('测算-外部分销'!I$39) -> 2.529556 | I41: =SUM('测算-高个子抖音'!J$39)+SUM('测算-高个子视频号'!J$39)+SUM('测算-天猫淘宝'!J$38)+SUM('测算-拼多多'!J$39)+SUM('测算-京东POP'!J$39)+SUM('测算-京东自营'!J$40)+SUM('测算-达播'!J$40)+SUM('测算-私域'!J$39)+SUM('测算-外部分销'!J$39) -> 1.245344 | J41: =SUM('测算-高个子抖音'!K$39)+SUM('测算-高个子视频号'!K$39)+SUM('测算-天猫淘宝'!K$38)+SUM('测算-拼多多'!K$39)+SUM('测算-京东POP'!K$39)+SUM('测算-京东自营'!K$40)+SUM('测算-达播'!K$40)+SUM('测算-私域'!K$39)+SUM('测算-外部分销'!K$39) -> 3.913159 | K41: =SUM('测算-高个子抖音'!L$39)+SUM('测算-高个子视频号'!L$39)+SUM('测算-天猫淘宝'!L$38)+SUM('测算-拼多多'!L$39)+SUM('测算-京东POP'!L$39)+SUM('测算-京东自营'!L$40)+SUM('测算-达播'!L$40)+SUM('测算-私域'!L$39)+SUM('测算-外部分销'!L$39) -> 4.59771 | L41: =SUM('测算-高个子抖音'!M$39)+SUM('测算-高个子视频号'!M$39)+SUM('测算-天猫淘宝'!M$38)+SUM('测算-拼多多'!M$39)+SUM('测算-京东POP'!M$39)+SUM('测算-京东自营'!M$40)+SUM('测算-达播'!M$40)+SUM('测算-私域'!M$39)+SUM('测算-外部分销'!M$39) -> 4.839552 | M41: =SUM('测算-高个子抖音'!N$39)+SUM('测算-高个子视频号'!N$39)+SUM('测算-天猫淘宝'!N$38)+SUM('测算-拼多多'!N$39)+SUM('测算-京东POP'!N$39)+SUM('测算-京东自营'!N$40)+SUM('测算-达播'!N$40)+SUM('测算-私域'!N$39)+SUM('测算-外部分销'!N$39) -> 6.9477594 | N41: =SUM('测算-高个子抖音'!O$39)+SUM('测算-高个子视频号'!O$39)+SUM('测算-天猫淘宝'!O$38)+SUM('测算-拼多多'!O$39)+SUM('测算-京东POP'!O$39)+SUM('测算-京东自营'!O$40)+SUM('测算-达播'!O$40)+SUM('测算-私域'!O$39)+SUM('测算-外部分销'!O$39) -> 5.1706365 | O41: =SUM('测算-高个子抖音'!P$39)+SUM('测算-高个子视频号'!P$39)+SUM('测算-天猫淘宝'!P$38)+SUM('测算-拼多多'!P$39)+SUM('测算-京东POP'!P$39)+SUM('测算-京东自营'!P$40)+SUM('测算-达播'!P$40)+SUM('测算-私域'!P$39)+SUM('测算-外部分销'!P$39) -> 6.4513983 | ... S41: =SUM('测算-高个子抖音'!T$39)+SUM('测算-高个子视频号'!T$39)+SUM('测算-天猫淘宝'!T$38)+SUM('测算-拼多多'!T$39)+SUM('测算-京东POP'!T$39)+SUM('测算-京东自营'!T$40)+SUM('测算-达播'!T$40)+SUM('测算-私域'!T$39)+SUM('测算-外部分销'!T$39) -> 8.5509499 | U41: =SUM('测算-高个子抖音'!V$39)+SUM('测算-高个子视频号'!V$39)+SUM('测算-天猫淘宝'!V$38)+SUM('测算-拼多多'!V$39)+SUM('测算-京东POP'!V$39)+SUM('测算-京东自营'!V$40)+SUM('测算-达播'!V$40)+SUM('测算-私域'!V$39)+SUM('测算-外部分销'!V$39) -> 70.189709 | V41: =SUM('测算-高个子抖音'!W$39)+SUM('测算-高个子视频号'!W$39)+SUM('测算-天猫淘宝'!W$38)+SUM('测算-拼多多'!W$39)+SUM('测算-京东POP'!W$39)+SUM('测算-京东自营'!W$40)+SUM('测算-达播'!W$40)+SUM('测算-私域'!W$39)+SUM('测算-外部分销'!W$39) -> 46.116628
D42: 仓储费用 | E42: 渠道测算费用明细 | F42: 各渠道测算表汇总 | H42: =SUM('测算-高个子抖音'!I$40)+SUM('测算-高个子视频号'!I$40)+SUM('测算-天猫淘宝'!I$39)+SUM('测算-拼多多'!I$40)+SUM('测算-京东POP'!I$40)+SUM('测算-达播'!I$41)+SUM('测算-私域'!I$40)+SUM('测算-外部分销'!I$40) -> 6.9570642 | I42: =SUM('测算-高个子抖音'!J$40)+SUM('测算-高个子视频号'!J$40)+SUM('测算-天猫淘宝'!J$39)+SUM('测算-拼多多'!J$40)+SUM('测算-京东POP'!J$40)+SUM('测算-达播'!J$41)+SUM('测算-私域'!J$40)+SUM('测算-外部分销'!J$40) -> 7.5715273 | J42: =SUM('测算-高个子抖音'!K$40)+SUM('测算-高个子视频号'!K$40)+SUM('测算-天猫淘宝'!K$39)+SUM('测算-拼多多'!K$40)+SUM('测算-京东POP'!K$40)+SUM('测算-京东自营'!K$41)+SUM('测算-达播'!K$41)+SUM('测算-私域'!K$40)+SUM('测算-外部分销'!K$40) -> 7.7176273 | K42: =SUM('测算-高个子抖音'!L$40)+SUM('测算-高个子视频号'!L$40)+SUM('测算-天猫淘宝'!L$39)+SUM('测算-拼多多'!L$40)+SUM('测算-京东POP'!L$40)+SUM('测算-京东自营'!L$41)+SUM('测算-达播'!L$41)+SUM('测算-私域'!L$40)+SUM('测算-外部分销'!L$40) -> 9.4444696 | L42: =SUM('测算-高个子抖音'!M$40)+SUM('测算-高个子视频号'!M$40)+SUM('测算-天猫淘宝'!M$39)+SUM('测算-拼多多'!M$40)+SUM('测算-京东POP'!M$40)+SUM('测算-京东自营'!M$41)+SUM('测算-达播'!M$41)+SUM('测算-私域'!M$40)+SUM('测算-外部分销'!M$40) -> 9.8821581 | M42: =SUM('测算-高个子抖音'!N$40)+SUM('测算-高个子视频号'!N$40)+SUM('测算-天猫淘宝'!N$39)+SUM('测算-拼多多'!N$40)+SUM('测算-京东POP'!N$40)+SUM('测算-京东自营'!N$41)+SUM('测算-达播'!N$41)+SUM('测算-私域'!N$40)+SUM('测算-外部分销'!N$40) -> 22.532769 | N42: =SUM('测算-高个子抖音'!O$40)+SUM('测算-高个子视频号'!O$40)+SUM('测算-天猫淘宝'!O$39)+SUM('测算-拼多多'!O$40)+SUM('测算-京东POP'!O$40)+SUM('测算-京东自营'!O$41)+SUM('测算-达播'!O$41)+SUM('测算-私域'!O$40)+SUM('测算-外部分销'!O$40) -> 12.320607 | O42: =SUM('测算-高个子抖音'!P$40)+SUM('测算-高个子视频号'!P$40)+SUM('测算-天猫淘宝'!P$39)+SUM('测算-拼多多'!P$40)+SUM('测算-京东POP'!P$40)+SUM('测算-京东自营'!P$41)+SUM('测算-达播'!P$41)+SUM('测算-私域'!P$40)+SUM('测算-外部分销'!P$40) -> 16.478178 | P42: =SUM('测算-高个子抖音'!Q$40)+SUM('测算-高个子视频号'!Q$40)+SUM('测算-天猫淘宝'!Q$39)+SUM('测算-拼多多'!Q$40)+SUM('测算-京东POP'!Q$40)+SUM('测算-京东自营'!Q$41)+SUM('测算-达播'!Q$41)+SUM('测算-私域'!Q$40)+SUM('测算-外部分销'!Q$40) -> 20.838558 | Q42: =SUM('测算-高个子抖音'!R$40)+SUM('测算-高个子视频号'!R$40)+SUM('测算-天猫淘宝'!R$39)+SUM('测算-拼多多'!R$40)+SUM('测算-京东POP'!R$40)+SUM('测算-京东自营'!R$41)+SUM('测算-达播'!R$41)+SUM('测算-私域'!R$40)+SUM('测算-外部分销'!R$40) -> 22.537078 | ... S42: =SUM('测算-高个子抖音'!T$40)+SUM('测算-高个子视频号'!T$40)+SUM('测算-天猫淘宝'!T$39)+SUM('测算-拼多多'!T$40)+SUM('测算-京东POP'!T$40)+SUM('测算-京东自营'!T$41)+SUM('测算-达播'!T$41)+SUM('测算-私域'!T$40)+SUM('测算-外部分销'!T$40) -> 23.32296 | U42: =SUM('测算-高个子抖音'!V$40)+SUM('测算-高个子视频号'!V$40)+SUM('测算-天猫淘宝'!V$39)+SUM('测算-拼多多'!V$40)+SUM('测算-京东POP'!V$40)+SUM('测算-京东自营'!V$41)+SUM('测算-达播'!V$41)+SUM('测算-私域'!V$40)+SUM('测算-外部分销'!V$40) -> 215.07159 | V42: =SUM('测算-高个子抖音'!W$40)+SUM('测算-高个子视频号'!W$40)+SUM('测算-天猫淘宝'!W$39)+SUM('测算-拼多多'!W$40)+SUM('测算-京东POP'!W$40)+SUM('测算-京东自营'!W$41)+SUM('测算-达播'!W$41)+SUM('测算-私域'!W$40)+SUM('测算-外部分销'!W$40) -> 122.87651
C43: 人工成本 | H43: =SUM(H44:H46) -> 41.826251 | I43: =SUM(I44:I46) -> 33.846583 | J43: =SUM(J44:J46) -> 47.037375 | K43: =SUM(K44:K46) -> 45.168611 | L43: =SUM(L44:L46) -> 50.566793 | M43: =SUM(M44:M46) -> 52.905912 | N43: =SUM(N44:N46) -> 55.408323 | O43: =SUM(O44:O46) -> 57.795207 | ... S43: =SUM(S44:S46) -> 61.107852 | U43: =SUM(U44:U46) -> 629.38475 | V43: =SUM(V44:V46) -> 358.03322
...

Sheet 总表-渠道二维汇总
A1: 返回目录 | F1: 渠道总贡献（万元） | U1: 抖音（万元） | AJ1: 视频号（万元） | AY1: 天猫淘宝（万元） | BN1: 拼多多（万元） | CC1: 京东POP（万元） | CR1: 京东自营（万元） | DG1: 达播（万元） | DV1: 私域（万元） | EK1: 外部分销（万元）
E2: 费用科目 | F2: 2026-01 | G2: 2026-02 | H2: 2026-03 | I2: 2026-04 | J2: 2026-05 | K2: 2026-06 | L2: 2026-07 | M2: 2026-08 | N2: 2026-09 | O2: 2026-10 | P2: 2026-11 | Q2: 2026-12 | R2: 全年合计 | S2: 中期合计 | U2: 2026-01 | V2: 2026-02 | W2: 2026-03 | X2: 2026-04 | Y2: 2026-05 | Z2: 2026-06 | AA2: 2026-07 | AB2: 2026-08 | AC2: 2026-09 | AD2: 2026-10 | AE2: 2026-11 | AF2: 2026-12 | AG2: 全年合计 | AH2: 中期合计 | AJ2: 2026-01 | AK2: 2026-02 | AL2: 2026-03 | AM2: 2026-04 | AN2: 2026-05 | AO2: 2026-06 | AP2: 2026-07 | AQ2: 2026-08 | AR2: 2026-09 | AS2: 2026-10 | AT2: 2026-11 | AU2: 2026-12 | AV2: 全年合计 | AW2: 中期合计 | AY2: 2026-01 | AZ2: 2026-02 | BA2: 2026-03 | BB2: 2026-04 | BC2: 2026-05 | BD2: 2026-06 | BE2: 2026-07 | BF2: 2026-08 | BG2: 2026-09 | BH2: 2026-10 | BI2: 2026-11 | BJ2: 2026-12 | BK2: 全年合计 | BL2: 中期合计 | BN2: 2026-01 | BO2: 2026-02 | BP2: 2026-03 | BQ2: 2026-04 | BR2: 2026-05 | BS2: 2026-06 | BT2: 2026-07 | BU2: 2026-08 | BV2: 2026-09 | BW2: 2026-10 | BX2: 2026-11 | BY2: 2026-12 | BZ2: 全年合计 | CA2: 中期合计 | CC2: 2026-01 | CD2: 2026-02 | CE2: 2026-03 | CF2: 2026-04 | CG2: 2026-05 | CH2: 2026-06 | CI2: 2026-07 | CJ2: 2026-08 | CK2: 2026-09 | CL2: 2026-10 | CM2: 2026-11 | CN2: 2026-12 | CO2: 全年合计 | CP2: 中期合计 | CR2: 2026-01 | CS2: 2026-02 | CT2: 2026-03 | CU2: 2026-04 | CV2: 2026-05 | CW2: 2026-06 | CX2: 2026-07 | CY2: 2026-08 | CZ2: 2026-09 | DA2: 2026-10 | DB2: 2026-11 | DC2: 2026-12 | DD2: 全年合计 | DE2: 中期合计 | DG2: 2026-01 | DH2: 2026-02 | DI2: 2026-03 | DJ2: 2026-04 | DK2: 2026-05 | DL2: 2026-06 | DM2: 2026-07 | DN2: 2026-08 | DO2: 2026-09 | DP2: 2026-10 | DQ2: 2026-11 | DR2: 2026-12 | DS2: 全年合计 | DT2: 中期合计 | DV2: 2026-01 | DW2: 2026-02 | DX2: 2026-03 | DY2: 2026-04 | DZ2: 2026-05 | EA2: 2026-06 | EB2: 2026-07 | EC2: 2026-08 | ED2: 2026-09 | EE2: 2026-10 | EF2: 2026-11 | EG2: 2026-12 | EH2: 全年合计 | EI2: 中期合计 | EK2: 2026-01 | EL2: 2026-02 | EM2: 2026-03 | EN2: 2026-04 | EO2: 2026-05 | EP2: 2026-06 | EQ2: 2026-07 | ER2: 2026-08 | ES2: 2026-09 | ET2: 2026-10 | EU2: 2026-11 | EV2: 2026-12 | EW2: 全年合计 | EX2: 中期合计
B3: 主营业务收入 | F3: =SUM(U3,AJ3,AY3,BN3,CC3,CR3,DG3,DV3,EK3) -> 1096.5403 | G3: =SUM(V3,AK3,AZ3,BO3,CD3,CS3,DH3,DW3,EL3) -> 664.95961 | H3: =SUM(W3,AL3,BA3,BP3,CE3,CT3,DI3,DX3,EM3) -> 1012.2948 | I3: =SUM(X3,AM3,BB3,BQ3,CF3,CU3,DJ3,DY3,EN3) -> 977.84975 | J3: =SUM(Y3,AN3,BC3,BR3,CG3,CV3,DK3,DZ3,EO3) -> 1218.1032 | K3: =SUM(Z3,AO3,BD3,BS3,CH3,CW3,DL3,EA3,EP3) -> 1240.5906 | L3: =SUM(AA3,AP3,BE3,BT3,CI3,CX3,DM3,EB3,EQ3) -> 791.84389 | M3: =SUM(AB3,AQ3,BF3,BU3,CJ3,CY3,DN3,EC3,ER3) -> 1045.5994 | ... Q3: =SUM(AF3,AU3,BJ3,BY3,CN3,DC3,DR3,EG3,EV3) -> 1463.1062 | R3: =SUM(F3:Q3) -> 13949.584 | S3: =SUM(L3:Q3) -> 7739.2455 | U3: ='测算-高个子抖音'!I$8 -> 412.73609 | V3: ='测算-高个子抖音'!J$8 -> 236.30884 | W3: ='测算-高个子抖音'!K$8 -> 480.96785 | X3: ='测算-高个子抖音'!L$8 -> 290.19738 | Y3: ='测算-高个子抖音'!M$8 -> 383.28089 | Z3: ='测算-高个子抖音'!N$8 -> 271.5265 | AA3: ='测算-高个子抖音'!O$8 -> 187.83606 | AB3: ='测算-高个子抖音'!P$8 -> 251.22106 | ... AF3: ='测算-高个子抖音'!T$8 -> 355.57443 | AG3: ='测算-高个子抖音'!V$8 -> 3948.3537 | AH3: ='测算-高个子抖音'!W$8 -> 1873.3361 | AJ3: ='测算-高个子视频号'!I$8 -> 15.6332 | AK3: ='测算-高个子视频号'!J$8 -> 5.3377 | AL3: ='测算-高个子视频号'!K$8 -> 11.32825 | AM3: ='测算-高个子视频号'!L$8 -> 7.4995 | AN3: ='测算-高个子视频号'!M$8 -> 67.386525 | AO3: ='测算-高个子视频号'!N$8 -> 70.535852 | AP3: ='测算-高个子视频号'!O$8 -> 52.87565 | AQ3: ='测算-高个子视频号'!P$8 -> 70.718462 | ... AU3: ='测算-高个子视频号'!T$8 -> 100.09382 | AV3: ='测算-高个子视频号'!V$8 -> 705.06316 | AW3: ='测算-高个子视频号'!W$8 -> 527.34213 | AY3: ='测算-天猫淘宝'!I$7 -> 27.701168 | AZ3: ='测算-天猫淘宝'!J$7 -> 14.251386 | BA3: ='测算-天猫淘宝'!K$7 -> 32.562117 | BB3: ='测算-天猫淘宝'!L$7 -> 34.249649 | BC3: ='测算-天猫淘宝'!M$7 -> 32.59645 | BD3: ='测算-天猫淘宝'!N$7 -> 26.272108 | BE3: ='测算-天猫淘宝'!O$7 -> 24.189839 | BF3: ='测算-天猫淘宝'!P$7 -> 32.352665 | ... BJ3: ='测算-天猫淘宝'!T$7 -> 45.791464 | BK3: ='测算-天猫淘宝'!V$7 -> 408.88421 | BL3: ='测算-天猫淘宝'!W$7 -> 241.25133 | BN3: ='测算-拼多多'!I$8 -> 0.154536 | BO3: ='测算-拼多多'!J$8 -> 0.276269 | BP3: ='测算-拼多多'!K$8 -> 0.366398 | BQ3: ='测算-拼多多'!L$8 -> 0.117881 | BR3: ='测算-拼多多'!M$8 -> 0.451221 | BS3: ='测算-拼多多'!N$8 -> 4.910275 | BT3: ='测算-拼多多'!O$8 -> 2.9054295 | BU3: ='测算-拼多多'!P$8 -> 3.8858625 | ... BY3: ='测算-拼多多'!T$8 -> 5.49999 | BZ3: ='测算-拼多多'!V$8 -> 35.253158 | CA3: ='测算-拼多多'!W$8 -> 28.976578 | CC3: ='测算-京东POP'!I$8 -> 13.6692 | CD3: ='测算-京东POP'!J$8 -> 8.572073 | CE3: ='测算-京东POP'!K$8 -> 23.263656 | CF3: ='测算-京东POP'!L$8 -> 19.4663 | CG3: ='测算-京东POP'!M$8 -> 19.221455 | CH3: ='测算-京东POP'!N$8 -> 16.670737 | CI3: ='测算-京东POP'!O$8 -> 25.234315 | CJ3: ='测算-京东POP'!P$8 -> 33.749598 | ... CN3: ='测算-京东POP'!T$8 -> 47.768662 | CO3: ='测算-京东POP'!V$8 -> 352.53158 | CP3: ='测算-京东POP'!W$8 -> 251.66816 | CR3: ='测算-京东自营'!I$7 -> 400.66294 | CS3: ='测算-京东自营'!J$7 -> 301.1688 | CT3: ='测算-京东自营'!K$7 -> 40.52241 | CU3: ='测算-京东自营'!L$7 -> 438.91121 | CV3: ='测算-京东自营'!M$7 -> 446.22897 | CW3: ='测算-京东自营'!N$7 -> 660.27604 | CX3: ='测算-京东自营'!O$7 -> 322.50669 | CY3: ='测算-京东自营'!P$7 -> 431.33611 | ... DC3: ='测算-京东自营'!T$7 -> 610.50649 | DD3: ='测算-京东自营'!V$7 -> 5504.2105 | DE3: ='测算-京东自营'!W$7 -> 3216.4402 | DG3: ='测算-达播'!I$8 -> 51.673564 | DH3: ='测算-达播'!J$8 -> 4.2376 | DI3: ='测算-达播'!K$8 -> 190.03228 | DJ3: ='测算-达播'!L$8 -> 37.810497 | DK3: ='测算-达播'!M$8 -> 81.138963 | DL3: ='测算-达播'!N$8 -> 27.381935 | DM3: ='测算-达播'!O$8 -> 86.671095 | DN3: ='测算-达播'!P$8 -> 115.91813 | ... DR3: ='测算-达播'!T$8 -> 164.06874 | DS3: ='测算-达播'!V$8 -> 1256.6674 | DT3: ='测算-达播'!W$8 -> 864.39259 | DV3: ='测算-私域'!I$8 -> 24.7803 | DW3: ='测算-私域'!J$8 -> 7.8601 | DX3: ='测算-私域'!K$8 -> 26.021881 | DY3: ='测算-私域'!L$8 -> 17.22148 | DZ3: ='测算-私域'!M$8 -> 18.57858 | EA3: ='测算-私域'!N$8 -> 20.1019 | EB3: ='测算-私域'!O$8 -> 35.9514 | EC3: ='测算-私域'!P$8 -> 34.632075 | ... EG3: ='测算-私域'!T$8 -> 32.198575 | EH3: ='测算-私域'!V$8 -> 315.10419 | EI3: ='测算-私域'!W$8 -> 200.53995 | EK3: ='测算-外部分销'!I$8 -> 149.52933 | EL3: ='测算-外部分销'!J$8 -> 86.946838 | EM3: ='测算-外部分销'!K$8 -> 207.22994 | EN3: ='测算-外部分销'!L$8 -> 132.37585 | EO3: ='测算-外部分销'!M$8 -> 169.22013 | EP3: ='测算-外部分销'!N$8 -> 142.91523 | EQ3: ='测算-外部分销'!O$8 -> 53.67342 | ER3: ='测算-外部分销'!P$8 -> 71.785438 | ... EV3: ='测算-外部分销'!T$8 -> 101.60401 | EW3: ='测算-外部分销'!V$8 -> 1423.5158 | EX3: ='测算-外部分销'!W$8 -> 535.29849
